Workbook

Sheet A4206 - Orden1
A1: CodTramoMT | B1: CodTramoMTPadre | C1: Orden | D1: Longitud
A2: 19099438 | B2: 2165177 | C2: =IF(B2=0,1,VLOOKUP(B2,A$2:C$288,3,FALSE)+1) -> 50 | D2: 34.27
A3: 19286313 | B3: 2236619 | C3: =IF(B3=0,1,VLOOKUP(B3,A$2:C$288,3,FALSE)+1) -> 70 | D3: 33.08
A4: 19286320 | B4: 2198646 | C4: =IF(B4=0,1,VLOOKUP(B4,A$2:C$288,3,FALSE)+1) -> 79 | D4: 45.83
A5: 19286327 | B5: 2342326 | C5: =IF(B5=0,1,VLOOKUP(B5,A$2:C$288,3,FALSE)+1) -> 67 | D5: 48.43
A6: 19286334 | B6: 2342319 | C6: =IF(B6=0,1,VLOOKUP(B6,A$2:C$288,3,FALSE)+1) -> 65 | D6: 23.37
A7: 19491724 | B7: 19491732 | C7: =IF(B7=0,1,VLOOKUP(B7,A$2:C$288,3,FALSE)+1) -> 74 | D7: 18.47
A8: 19491732 | B8: 2164769 | C8: =IF(B8=0,1,VLOOKUP(B8,A$2:C$288,3,FALSE)+1) -> 73 | D8: 31.42
A9: 19492829 | B9: 2253026 | C9: =IF(B9=0,1,VLOOKUP(B9,A$2:C$288,3,FALSE)+1) -> 86 | D9: 1
A10: 2078334 | B10: 2078355 | C10: =IF(B10=0,1,VLOOKUP(B10,A$2:C$288,3,FALSE)+1) -> 88 | D10: 11.73
A11: 2078348 | B11: 2078355 | C11: =IF(B11=0,1,VLOOKUP(B11,A$2:C$288,3,FALSE)+1) -> 88 | D11: 25.47
A12: 2078355 | B12: 2078362 | C12: =IF(B12=0,1,VLOOKUP(B12,A$2:C$288,3,FALSE)+1) -> 87 | D12: 17.62
A13: 2078362 | B13: 2078369 | C13: =IF(B13=0,1,VLOOKUP(B13,A$2:C$288,3,FALSE)+1) -> 86 | D13: 39.72
... A288: 9357147 | B288: 9357140 | C288: =IF(B288=0,1,VLOOKUP(B288,A$2:C$288,3,FALSE)+1) -> 59 | D288: 3

Sheet A4206 - Tramos
A1: CodSalidaMT | B1: CodTramoMT | C1: CodTramoMTPadre | D1: Longitud | E1: Tramos Finales | F1: {=_xlfn.UNIQUE(E2:E288)} | H1: Suma de longitudes | I1: Iteraciones | J1: 1 | K1: 2 | L1: 3 | M1: 4 | N1: 5 | O1: 6 | P1: 7 | Q1: 8 | R1: 9 | S1: 10 | T1: 11 | U1: 12 | V1: 13 | W1: 14 | X1: 15 | Y1: 16 | Z1: 17 | AA1: 18 | AB1: 19 | AC1: 20 | AD1: 21 | AE1: 22 | AF1: 23 | AG1: 24 | AH1: 25 | AI1: 26 | AJ1: 27 | AK1: 28 | AL1: 29 | AM1: 30 | AN1: 31 | AO1: 32 | AP1: 33 | AQ1: 34 | AR1: 35 | AS1: 36 | AT1: 37 | AU1: 38 | AV1: 39 | AW1: 40 | AX1: 41 | AY1: 42 | AZ1: 43 | BA1: 44 | BB1: 45 | BC1: 46 | BD1: 47 | BE1: 48 | BF1: 49 | BG1: 50 | BH1: 51 | BI1: 52 | BJ1: 53 | BK1: 54 | BL1: 55 | BM1: 56 | BN1: 57 | BO1: 58 | BP1: 59 | BQ1: 60 | BR1: 61 | BS1: 62 | BT1: 63 | BU1: 64 | BV1: 65 | BW1: 66 | BX1: 67 | BY1: 68 | BZ1: 69 | CA1: 70 | CB1: 71 | CC1: 72 | CD1: 73 | CE1: 74 | CF1: 75 | CG1: 76 | CH1: 77 | CI1: 78 | CJ1: 79 | CK1: 80 | CL1: 81 | CM1: 82 | CN1: 83 | CO1: 84 | CP1: 85 | CQ1: 86 | CR1: 87 | CS1: 88 | CT1: 89 | CU1: 90 | CV1: 91 | CW1: 92 | CX1: 93 | CY1: 94 | CZ1: 95 | DA1: 96 | DB1: 97 | DC1: 98 | DD1: 99 | DE1: 100
A2: A4243 | B2: =NODOS!X2 -> 9249850 | C2: =NODOS!Y2 -> 0 | D2: =NODOS!AA2 -> 28.45 | E2: =IF(IFERROR(VLOOKUP(B2,$C:$C,1,FALSE),1)=1,B2,"") | F2: 7869061 | H2: {=SUM(IFERROR(_xlfn.XLOOKUP(J2:Z2,$B:$B,$D:$D),0))} -> 562.78 | I2: =COUNTIF(J2:DE2,"<>""")-COUNTBLANK(J2:DE2) -> 10 | J2: =F2 -> 7869061 | K2: =IFERROR(_xlfn.XLOOKUP(J2,$B:$B,$C:$C),"") -> 7869054 | L2: =IFERROR(_xlfn.XLOOKUP(K2,$B:$B,$C:$C),"") -> 2167984 | M2: =IFERROR(_xlfn.XLOOKUP(L2,$B:$B,$C:$C),"") -> 2167977 | N2: =IFERROR(_xlfn.XLOOKUP(M2,$B:$B,$C:$C),"") -> 2167970 | O2: =IFERROR(_xlfn.XLOOKUP(N2,$B:$B,$C:$C),"") -> 2167963 | P2: =IFERROR(_xlfn.XLOOKUP(O2,$B:$B,$C:$C),"") -> 2167956 | Q2: =IFERROR(_xlfn.XLOOKUP(P2,$B:$B,$C:$C),"") -> 2167949 | R2: =IFERROR(_xlfn.XLOOKUP(Q2,$B:$B,$C:$C),"") -> 9249850 | ... DE2: =IFERROR(_xlfn.XLOOKUP(DD2,$B:$B,$C:$C),"")
A3: A4243 | B3: =NODOS!X3 -> 2167949 | C3: =NODOS!Y3 -> 9249850 | D3: =NODOS!AA3 -> 90.02 | E3: =IF(IFERROR(VLOOKUP(B3,$C:$C,1,FALSE),1)=1,B3,"") | F3: 2168040 | H3: {=SUM(IFERROR(_xlfn.XLOOKUP(J3:Z3,$B:$B,$D:$D),0))} -> 776.91 | I3: =COUNTIF(J3:DE3,"<>""")-COUNTBLANK(J3:DE3) -> 23 | J3: =F3 -> 2168040 | K3: =IFERROR(_xlfn.XLOOKUP(J3,$B:$B,$C:$C),"") -> 2168047 | L3: =IFERROR(_xlfn.XLOOKUP(K3,$B:$B,$C:$C),"") -> 2168033 | M3: =IFERROR(_xlfn.XLOOKUP(L3,$B:$B,$C:$C),"") -> 2168026 | N3: =IFERROR(_xlfn.XLOOKUP(M3,$B:$B,$C:$C),"") -> 9250045 | O3: =IFERROR(_xlfn.XLOOKUP(N3,$B:$B,$C:$C),"") -> 9250040 | P3: =IFERROR(_xlfn.XLOOKUP(O3,$B:$B,$C:$C),"") -> 9250035 | Q3: =IFERROR(_xlfn.XLOOKUP(P3,$B:$B,$C:$C),"") -> 9250030 | R3: =IFERROR(_xlfn.XLOOKUP(Q3,$B:$B,$C:$C),"") -> 9250025 | ... DE3: =IFERROR(_xlfn.XLOOKUP(DD3,$B:$B,$C:$C),"")
A4: A4243 | B4: =NODOS!X4 -> 2167956 | C4: =NODOS!Y4 -> 2167949 | D4: =NODOS!AA4 -> 90.22 | E4: =IF(IFERROR(VLOOKUP(B4,$C:$C,1,FALSE),1)=1,B4,"") | F4: 2150828 | H4: {=SUM(IFERROR(_xlfn.XLOOKUP(J4:Z4,$B:$B,$D:$D),0))} -> 636 | I4: =COUNTIF(J4:DE4,"<>""")-COUNTBLANK(J4:DE4) -> 28 | J4: =F4 -> 2150828 | K4: =IFERROR(_xlfn.XLOOKUP(J4,$B:$B,$C:$C),"") -> 2150842 | L4: =IFERROR(_xlfn.XLOOKUP(K4,$B:$B,$C:$C),"") -> 2168075 | M4: =IFERROR(_xlfn.XLOOKUP(L4,$B:$B,$C:$C),"") -> 2168068 | N4: =IFERROR(_xlfn.XLOOKUP(M4,$B:$B,$C:$C),"") -> 2168061 | O4: =IFERROR(_xlfn.XLOOKUP(N4,$B:$B,$C:$C),"") -> 2168054 | P4: =IFERROR(_xlfn.XLOOKUP(O4,$B:$B,$C:$C),"") -> 2168047 | Q4: =IFERROR(_xlfn.XLOOKUP(P4,$B:$B,$C:$C),"") -> 2168033 | R4: =IFERROR(_xlfn.XLOOKUP(Q4,$B:$B,$C:$C),"") -> 2168026 | ... DE4: =IFERROR(_xlfn.XLOOKUP(DD4,$B:$B,$C:$C),"")
A5: A4243 | B5: =NODOS!X5 -> 2167963 | C5: =NODOS!Y5 -> 2167956 | D5: =NODOS!AA5 -> 93.03 | E5: =IF(IFERROR(VLOOKUP(B5,$C:$C,1,FALSE),1)=1,B5,"") | F5: 2132681 | H5: {=SUM(IFERROR(_xlfn.XLOOKUP(J5:Z5,$B:$B,$D:$D),0))} -> 550.5 | I5: =COUNTIF(J5:DE5,"<>""")-COUNTBLANK(J5:DE5) -> 33 | J5: =F5 -> 2132681 | K5: =IFERROR(_xlfn.XLOOKUP(J5,$B:$B,$C:$C),"") -> 2132688 | L5: =IFERROR(_xlfn.XLOOKUP(K5,$B:$B,$C:$C),"") -> 2168096 | M5: =IFERROR(_xlfn.XLOOKUP(L5,$B:$B,$C:$C),"") -> 2168089 | N5: =IFERROR(_xlfn.XLOOKUP(M5,$B:$B,$C:$C),"") -> 2168082 | O5: =IFERROR(_xlfn.XLOOKUP(N5,$B:$B,$C:$C),"") -> 2150835 | P5: =IFERROR(_xlfn.XLOOKUP(O5,$B:$B,$C:$C),"") -> 2150842 | Q5: =IFERROR(_xlfn.XLOOKUP(P5,$B:$B,$C:$C),"") -> 2168075 | R5: =IFERROR(_xlfn.XLOOKUP(Q5,$B:$B,$C:$C),"") -> 2168068 | ... DE5: =IFERROR(_xlfn.XLOOKUP(DD5,$B:$B,$C:$C),"")
A6: A4243 | B6: =NODOS!X6 -> 2167970 | C6: =NODOS!Y6 -> 2167963 | D6: =NODOS!AA6 -> 48.01 | E6: =IF(IFERROR(VLOOKUP(B6,$C:$C,1,FALSE),1)=1,B6,"") | F6: 2132653 | H6: {=SUM(IFERROR(_xlfn.XLOOKUP(J6:Z6,$B:$B,$D:$D),0))} -> 561.65 | I6: =COUNTIF(J6:DE6,"<>""")-COUNTBLANK(J6:DE6) -> 35 | J6: =F6 -> 2132653 | K6: =IFERROR(_xlfn.XLOOKUP(J6,$B:$B,$C:$C),"") -> 2132660 | L6: =IFERROR(_xlfn.XLOOKUP(K6,$B:$B,$C:$C),"") -> 2132674 | M6: =IFERROR(_xlfn.XLOOKUP(L6,$B:$B,$C:$C),"") -> 2132688 | N6: =IFERROR(_xlfn.XLOOKUP(M6,$B:$B,$C:$C),"") -> 2168096 | O6: =IFERROR(_xlfn.XLOOKUP(N6,$B:$B,$C:$C),"") -> 2168089 | P6: =IFERROR(_xlfn.XLOOKUP(O6,$B:$B,$C:$C),"") -> 2168082 | Q6: =IFERROR(_xlfn.XLOOKUP(P6,$B:$B,$C:$C),"") -> 2150835 | R6: =IFERROR(_xlfn.XLOOKUP(Q6,$B:$B,$C:$C),"") -> 2150842 | ... DE6: =IFERROR(_xlfn.XLOOKUP(DD6,$B:$B,$C:$C),"")
A7: A4243 | B7: =NODOS!X7 -> 2167977 | C7: =NODOS!Y7 -> 2167970 | D7: =NODOS!AA7 -> 38.54 | E7: =IF(IFERROR(VLOOKUP(B7,$C:$C,1,FALSE),1)=1,B7,"") | F7: 2131940 | H7: {=SUM(IFERROR(_xlfn.XLOOKUP(J7:Z7,$B:$B,$D:$D),0))} -> 690.69 | I7: =COUNTIF(J7:DE7,"<>""")-COUNTBLANK(J7:DE7) -> 42 | J7: =F7 -> 2131940 | K7: =IFERROR(_xlfn.XLOOKUP(J7,$B:$B,$C:$C),"") -> 2168138 | L7: =IFERROR(_xlfn.XLOOKUP(K7,$B:$B,$C:$C),"") -> 2168131 | M7: =IFERROR(_xlfn.XLOOKUP(L7,$B:$B,$C:$C),"") -> 2168124 | N7: =IFERROR(_xlfn.XLOOKUP(M7,$B:$B,$C:$C),"") -> 2168117 | O7: =IFERROR(_xlfn.XLOOKUP(N7,$B:$B,$C:$C),"") -> 2168110 | P7: =IFERROR(_xlfn.XLOOKUP(O7,$B:$B,$C:$C),"") -> 2132410 | Q7: =IFERROR(_xlfn.XLOOKUP(P7,$B:$B,$C:$C),"") -> 2132417 | R7: =IFERROR(_xlfn.XLOOKUP(Q7,$B:$B,$C:$C),"") -> 2168103 | ... DE7: =IFERROR(_xlfn.XLOOKUP(DD7,$B:$B,$C:$C),"")
A8: A4243 | B8: =NODOS!X8 -> 2167984 | C8: =NODOS!Y8 -> 2167977 | D8: =NODOS!AA8 -> 89.08 | E8: =IF(IFERROR(VLOOKUP(B8,$C:$C,1,FALSE),1)=1,B8,"") | F8: 2168173 | H8: {=SUM(IFERROR(_xlfn.XLOOKUP(J8:Z8,$B:$B,$D:$D),0))} -> 904.98 | I8: =COUNTIF(J8:DE8,"<>""")-COUNTBLANK(J8:DE8) -> 46 | J8: =F8 -> 2168173 | K8: =IFERROR(_xlfn.XLOOKUP(J8,$B:$B,$C:$C),"") -> 2168166 | L8: =IFERROR(_xlfn.XLOOKUP(K8,$B:$B,$C:$C),"") -> 2168159 | M8: =IFERROR(_xlfn.XLOOKUP(L8,$B:$B,$C:$C),"") -> 2168152 | N8: =IFERROR(_xlfn.XLOOKUP(M8,$B:$B,$C:$C),"") -> 2168145 | O8: =IFERROR(_xlfn.XLOOKUP(N8,$B:$B,$C:$C),"") -> 2168138 | P8: =IFERROR(_xlfn.XLOOKUP(O8,$B:$B,$C:$C),"") -> 2168131 | Q8: =IFERROR(_xlfn.XLOOKUP(P8,$B:$B,$C:$C),"") -> 2168124 | R8: =IFERROR(_xlfn.XLOOKUP(Q8,$B:$B,$C:$C),"") -> 2168117 | ... DE8: =IFERROR(_xlfn.XLOOKUP(DD8,$B:$B,$C:$C),"")
A9: A4243 | B9: =NODOS!X9 -> 7869054 | C9: =NODOS!Y9 -> 2167984 | D9: =NODOS!AA9 -> 76.14 | E9: =IF(IFERROR(VLOOKUP(B9,$C:$C,1,FALSE),1)=1,B9,"") | F9: 2149725 | H9: {=SUM(IFERROR(_xlfn.XLOOKUP(J9:Z9,$B:$B,$D:$D),0))} -> 851.76 | I9: =COUNTIF(J9:DE9,"<>""")-COUNTBLANK(J9:DE9) -> 57 | J9: =F9 -> 2149725 | K9: =IFERROR(_xlfn.XLOOKUP(J9,$B:$B,$C:$C),"") -> 2149739 | L9: =IFERROR(_xlfn.XLOOKUP(K9,$B:$B,$C:$C),"") -> 2168236 | M9: =IFERROR(_xlfn.XLOOKUP(L9,$B:$B,$C:$C),"") -> 2168229 | N9: =IFERROR(_xlfn.XLOOKUP(M9,$B:$B,$C:$C),"") -> 2168222 | O9: =IFERROR(_xlfn.XLOOKUP(N9,$B:$B,$C:$C),"") -> 2168208 | P9: =IFERROR(_xlfn.XLOOKUP(O9,$B:$B,$C:$C),"") -> 2168215 | Q9: =IFERROR(_xlfn.XLOOKUP(P9,$B:$B,$C:$C),"") -> 2166407 | R9: =IFERROR(_xlfn.XLOOKUP(Q9,$B:$B,$C:$C),"") -> 2168201 | ... DE9: =IFERROR(_xlfn.XLOOKUP(DD9,$B:$B,$C:$C),"")
A10: A4243 | B10: =NODOS!X10 -> 2167991 | C10: =NODOS!Y10 -> 7869054 | D10: =NODOS!AA10 -> 11.18 | E10: =IF(IFERROR(VLOOKUP(B10,$C:$C,1,FALSE),1)=1,B10,"") | F10: 2149683 | H10: {=SUM(IFERROR(_xlfn.XLOOKUP(J10:Z10,$B:$B,$D:$D),0))} -> 777.79 | I10: =COUNTIF(J10:DE10,"<>""")-COUNTBLANK(J10:DE10) -> 60 | J10: =F10 -> 2149683 | K10: =IFERROR(_xlfn.XLOOKUP(J10,$B:$B,$C:$C),"") -> 2149690 | L10: =IFERROR(_xlfn.XLOOKUP(K10,$B:$B,$C:$C),"") -> 2149697 | M10: =IFERROR(_xlfn.XLOOKUP(L10,$B:$B,$C:$C),"") -> 2149711 | N10: =IFERROR(_xlfn.XLOOKUP(M10,$B:$B,$C:$C),"") -> 2149739 | O10: =IFERROR(_xlfn.XLOOKUP(N10,$B:$B,$C:$C),"") -> 2168236 | P10: =IFERROR(_xlfn.XLOOKUP(O10,$B:$B,$C:$C),"") -> 2168229 | Q10: =IFERROR(_xlfn.XLOOKUP(P10,$B:$B,$C:$C),"") -> 2168222 | R10: =IFERROR(_xlfn.XLOOKUP(Q10,$B:$B,$C:$C),"") -> 2168208 | ... DE10: =IFERROR(_xlfn.XLOOKUP(DD10,$B:$B,$C:$C),"")
A11: A4243 | B11: =NODOS!X11 -> 7869061 | C11: =NODOS!Y11 -> 7869054 | D11: =NODOS!AA11 -> 9.29 | E11: =IF(IFERROR(VLOOKUP(B11,$C:$C,1,FALSE),1)=1,B11,"") -> 7869061 | F11: 9357147 | H11: {=SUM(IFERROR(_xlfn.XLOOKUP(J11:Z11,$B:$B,$D:$D),0))} -> 713.36 | I11: =COUNTIF(J11:DE11,"<>""")-COUNTBLANK(J11:DE11) -> 60 | J11: =F11 -> 9357147 | K11: =IFERROR(_xlfn.XLOOKUP(J11,$B:$B,$C:$C),"") -> 9357140 | L11: =IFERROR(_xlfn.XLOOKUP(K11,$B:$B,$C:$C),"") -> 7568364 | M11: =IFERROR(_xlfn.XLOOKUP(L11,$B:$B,$C:$C),"") -> 2149732 | N11: =IFERROR(_xlfn.XLOOKUP(M11,$B:$B,$C:$C),"") -> 2149739 | O11: =IFERROR(_xlfn.XLOOKUP(N11,$B:$B,$C:$C),"") -> 2168236 | P11: =IFERROR(_xlfn.XLOOKUP(O11,$B:$B,$C:$C),"") -> 2168229 | Q11: =IFERROR(_xlfn.XLOOKUP(P11,$B:$B,$C:$C),"") -> 2168222 | R11: =IFERROR(_xlfn.XLOOKUP(Q11,$B:$B,$C:$C),"") -> 2168208 | ... DE11: =IFERROR(_xlfn.XLOOKUP(DD11,$B:$B,$C:$C),"")
A12: A4243 | B12: =NODOS!X12 -> 2167998 | C12: =NODOS!Y12 -> 2167991 | D12: =NODOS!AA12 -> 83.97 | E12: =IF(IFERROR(VLOOKUP(B12,$C:$C,1,FALSE),1)=1,B12,"") | F12: 2149669 | H12: {=SUM(IFERROR(_xlfn.XLOOKUP(J12:Z12,$B:$B,$D:$D),0))} -> 730.9 | I12: =COUNTIF(J12:DE12,"<>""")-COUNTBLANK(J12:DE12) -> 61 | J12: =F12 -> 2149669 | K12: =IFERROR(_xlfn.XLOOKUP(J12,$B:$B,$C:$C),"") -> 2149676 | L12: =IFERROR(_xlfn.XLOOKUP(K12,$B:$B,$C:$C),"") -> 2149690 | M12: =IFERROR(_xlfn.XLOOKUP(L12,$B:$B,$C:$C),"") -> 2149697 | N12: =IFERROR(_xlfn.XLOOKUP(M12,$B:$B,$C:$C),"") -> 2149711 | O12: =IFERROR(_xlfn.XLOOKUP(N12,$B:$B,$C:$C),"") -> 2149739 | P12: =IFERROR(_xlfn.XLOOKUP(O12,$B:$B,$C:$C),"") -> 2168236 | Q12: =IFERROR(_xlfn.XLOOKUP(P12,$B:$B,$C:$C),"") -> 2168229 | R12: =IFERROR(_xlfn.XLOOKUP(Q12,$B:$B,$C:$C),"") -> 2168222 | ... DE12: =IFERROR(_xlfn.XLOOKUP(DD12,$B:$B,$C:$C),"")
A13: A4243 | B13: =NODOS!X13 -> 2168005 | C13: =NODOS!Y13 -> 2167998 | D13: =NODOS!AA13 -> 71.81 | E13: =IF(IFERROR(VLOOKUP(B13,$C:$C,1,FALSE),1)=1,B13,"") | F13: 2363051 | H13: {=SUM(IFERROR(_xlfn.XLOOKUP(J13:Z13,$B:$B,$D:$D),0))} -> 857.72 | I13: =COUNTIF(J13:DE13,"<>""")-COUNTBLANK(J13:DE13) -> 61 | J13: =F13 -> 2363051 | K13: =IFERROR(_xlfn.XLOOKUP(J13,$B:$B,$C:$C),"") -> 2343073 | L13: =IFERROR(_xlfn.XLOOKUP(K13,$B:$B,$C:$C),"") -> 2343087 | M13: =IFERROR(_xlfn.XLOOKUP(L13,$B:$B,$C:$C),"") -> 2363719 | N13: =IFERROR(_xlfn.XLOOKUP(M13,$B:$B,$C:$C),"") -> 2166393 | O13: =IFERROR(_xlfn.XLOOKUP(N13,$B:$B,$C:$C),"") -> 2166400 | P13: =IFERROR(_xlfn.XLOOKUP(O13,$B:$B,$C:$C),"") -> 2130229 | Q13: =IFERROR(_xlfn.XLOOKUP(P13,$B:$B,$C:$C),"") -> 2130236 | R13: =IFERROR(_xlfn.XLOOKUP(Q13,$B:$B,$C:$C),"") -> 2164995 | ... DE13: =IFERROR(_xlfn.XLOOKUP(DD13,$B:$B,$C:$C),"")
... A54: A4243 | B54: =NODOS!X54 -> 2168173 | C54: =NODOS!Y54 -> 2168166 | D54: =NODOS!AA54 -> 26.31 | E54: =IF(IFERROR(VLOOKUP(B54,$C:$C,1,FALSE),1)=1,B54,"") -> 2168173 | F54: 9249130 | H54: {=SUM(IFERROR(_xlfn.XLOOKUP(J54:Z54,$B:$B,$D:$D),0))} -> 176.8 | I54: =COUNTIF(J54:DE54,"<>""")-COUNTBLANK(J54:DE54) -> 99 | J54: =F54 -> 9249130 | K54: =IFERROR(_xlfn.XLOOKUP(J54,$B:$B,$C:$C),"") -> 9249135 | L54: =IFERROR(_xlfn.XLOOKUP(K54,$B:$B,$C:$C),"") -> 9249140 | M54: =IFERROR(_xlfn.XLOOKUP(L54,$B:$B,$C:$C),"") -> 9249145 | N54: =IFERROR(_xlfn.XLOOKUP(M54,$B:$B,$C:$C),"") -> 9249150 | O54: =IFERROR(_xlfn.XLOOKUP(N54,$B:$B,$C:$C),"") -> 9249155 | P54: =IFERROR(_xlfn.XLOOKUP(O54,$B:$B,$C:$C),"") -> 9249160 | Q54: =IFERROR(_xlfn.XLOOKUP(P54,$B:$B,$C:$C),"") -> 9249165 | R54: =IFERROR(_xlfn.XLOOKUP(Q54,$B:$B,$C:$C),"") -> 9249170 | ... DE54: =IFERROR(_xlfn.XLOOKUP(DD54,$B:$B,$C:$C),"")
A55: A4243 | B55: =NODOS!X55 -> 2168180 | C55: =NODOS!Y55 -> 2168166 | D55: =NODOS!AA55 -> 54.92 | E55: =IF(IFERROR(VLOOKUP(B55,$C:$C,1,FALSE),1)=1,B55,"")
A56: A4243 | B56: =NODOS!X56 -> 2168187 | C56: =NODOS!Y56 -> 2168180 | D56: =NODOS!AA56 -> 64.59 | E56: =IF(IFERROR(VLOOKUP(B56,$C:$C,1,FALSE),1)=1,B56,"")
A57: A4243 | B57: =NODOS!X57 -> 2168194 | C57: =NODOS!Y57 -> 2168187 | D57: =NODOS!AA57 -> 70.68 | E57: =IF(IFERROR(VLOOKUP(B57,$C:$C,1,FALSE),1)=1,B57,"")
A58: A4243 | B58: =NODOS!X58 -> 2168201 | C58: =NODOS!Y58 -> 2168194 | D58: =NODOS!AA58 -> 68.13 | E58: =IF(IFERROR(VLOOKUP(B58,$C:$C,1,FALSE),1)=1,B58,"")
A59: A4243 | B59: =NODOS!X59 -> 2165177 | C59: =NODOS!Y59 -> 2168201 | D59: =NODOS!AA59 -> 23.93 | E59: =IF(IFERROR(VLOOKUP(B59,$C:$C,1,FALSE),1)=1,B59,"")
A60: A4243 | B60: =NODOS!X60 -> 2166407 | C60: =NODOS!Y60 -> 2168201 | D60: =NODOS!AA60 -> 24.98 | E60: =IF(IFERROR(VLOOKUP(B60,$C:$C,1,FALSE),1)=1,B60,"")
A61: A4243 | B61: =NODOS!X61 -> 19099438 | C61: =NODOS!Y61 -> 2165177 | D61: =NODOS!AA61 -> 34.27 | E61: =IF(IFERROR(VLOOKUP(B61,$C:$C,1,FALSE),1)=1,B61,"")
A62: A4243 | B62: =NODOS!X62 -> 2168215 | C62: =NODOS!Y62 -> 2166407 | D62: =NODOS!AA62 -> 52 | E62: =IF(IFERROR(VLOOKUP(B62,$C:$C,1,FALSE),1)=1,B62,"")
A63: A4243 | B63: =NODOS!X63 -> 2165170 | C63: =NODOS!Y63 -> 19099438 | D63: =NODOS!AA63 -> 47.97 | E63: =IF(IFERROR(VLOOKUP(B63,$C:$C,1,FALSE),1)=1,B63,"")
A64: A4243 | B64: =NODOS!X64 -> 2168208 | C64: =NODOS!Y64 -> 2168215 | D64: =NODOS!AA64 -> 67.78 | E64: =IF(IFERROR(VLOOKUP(B64,$C:$C,1,FALSE),1)=1,B64,"")
A65: A4243 | B65: =NODOS!X65 -> 2164995 | C65: =NODOS!Y65 -> 2165170 | D65: =NODOS!AA65 -> 62.16 | E65: =IF(IFERROR(VLOOKUP(B65,$C:$C,1,FALSE),1)=1,B65,"")
A66: A4243 | B66: =NODOS!X66 -> 2168222 | C66: =NODOS!Y66 -> 2168208 | D66: =NODOS!AA66 -> 1.46 | E66: =IF(IFERROR(VLOOKUP(B66,$C:$C,1,FALSE),1)=1,B66,"")
... A288: A4243 | B288: =NODOS!X288 -> 9249130 | C288: =NODOS!Y288 -> 9249135 | D288: =NODOS!AA288 -> 1.7 | E288: =IF(IFERROR(VLOOKUP(B288,$C:$C,1,FALSE),1)=1,B288,"") -> 9249130

Sheet A4206 - Tramos Ordenados
A1: 0 | B1: 1 | C1: 2 | D1: 3 | E1: 4 | F1: 5 | G1: 6 | H1: 7 | I1: 8 | J1: 9 | K1: 10 | L1: 11 | M1: 12 | N1: 13 | O1: 14 | P1: 15 | Q1: 16 | R1: 17 | S1: 18 | T1: 19 | U1: 20 | V1: 21 | W1: 22 | X1: 23 | Y1: 24 | Z1: 25 | AA1: 26 | AB1: 27 | AC1: 28 | AD1: 29 | AE1: 30 | AF1: 31 | AG1: 32 | AH1: 33 | AI1: 34 | AJ1: 35 | AK1: 36 | AL1: 37 | AM1: 38 | AN1: 39 | AO1: 40 | AP1: 41 | AQ1: 42 | AR1: 43 | AS1: 44 | AT1: 45 | AU1: 46 | AV1: 47 | AW1: 48 | AX1: 49 | AY1: 50 | AZ1: 51 | BA1: 52 | BB1: 53 | BC1: 54 | BD1: 55 | BE1: 56 | BF1: 57 | BG1: 58 | BH1: 59 | BI1: 60 | BJ1: 61 | BK1: 62 | BL1: 63 | BM1: 64 | BN1: 65 | BO1: 66 | BP1: 67 | BQ1: 68 | BR1: 69 | BS1: 70 | BT1: 71 | BU1: 72 | BV1: 73 | BW1: 74 | BX1: 75 | BY1: 76 | BZ1: 77 | CA1: 78 | CB1: 79 | CC1: 80 | CD1: 81 | CE1: 82 | CF1: 83 | CG1: 84 | CH1: 85 | CI1: 86 | CJ1: 87 | CK1: 88 | CL1: 89 | CM1: 90 | CN1: 91 | CO1: 92 | CP1: 93 | CQ1: 94 | CR1: 95 | CS1: 96 | CT1: 97 | CU1: 98 | CV1: 99 | CW1: 100
A2: =IF( 'A4206 - Tramos'!$I2-A$1>0,OFFSET('A4206 - Tramos'!$I2,0,'A4206 - Tramos'!$I2-A$1),ROW('A4206 - Tramos'!I2)-1) -> 0 | B2: =IF( 'A4206 - Tramos'!$I2-B$1>0,OFFSET('A4206 - Tramos'!$I2,0,'A4206 - Tramos'!$I2-B$1),ROW('A4206 - Tramos'!J2)-1) -> 9249850 | C2: =IF( 'A4206 - Tramos'!$I2-C$1>0,OFFSET('A4206 - Tramos'!$I2,0,'A4206 - Tramos'!$I2-C$1),ROW('A4206 - Tramos'!K2)-1) -> 2167949 | D2: =IF( 'A4206 - Tramos'!$I2-D$1>0,OFFSET('A4206 - Tramos'!$I2,0,'A4206 - Tramos'!$I2-D$1),ROW('A4206 - Tramos'!L2)-1) -> 2167956 | E2: =IF( 'A4206 - Tramos'!$I2-E$1>0,OFFSET('A4206 - Tramos'!$I2,0,'A4206 - Tramos'!$I2-E$1),ROW('A4206 - Tramos'!M2)-1) -> 2167963 | F2: =IF( 'A4206 - Tramos'!$I2-F$1>0,OFFSET('A4206 - Tramos'!$I2,0,'A4206 - Tramos'!$I2-F$1),ROW('A4206 - Tramos'!N2)-1) -> 2167970 | G2: =IF( 'A4206 - Tramos'!$I2-G$1>0,OFFSET('A4206 - Tramos'!$I2,0,'A4206 - Tramos'!$I2-G$1),ROW('A4206 - Tramos'!O2)-1) -> 2167977 | H2: =IF( 'A4206 - Tramos'!$I2-H$1>0,OFFSET('A4206 - Tramos'!$I2,0,'A4206 - Tramos'!$I2-H$1),ROW('A4206 - Tramos'!P2)-1) -> 2167984 | ... CW2: =IF( 'A4206 - Tramos'!$I2-CW$1>0,OFFSET('A4206 - Tramos'!$I2,0,'A4206 - Tramos'!$I2-CW$1),ROW('A4206 - Tramos'!DE2)-1) -> 1
A3: =IF( 'A4206 - Tramos'!$I3-A$1>0,OFFSET('A4206 - Tramos'!$I3,0,'A4206 - Tramos'!$I3-A$1),ROW('A4206 - Tramos'!I3)-1) -> 0 | B3: =IF( 'A4206 - Tramos'!$I3-B$1>0,OFFSET('A4206 - Tramos'!$I3,0,'A4206 - Tramos'!$I3-B$1),ROW('A4206 - Tramos'!J3)-1) -> 9249850 | C3: =IF( 'A4206 - Tramos'!$I3-C$1>0,OFFSET('A4206 - Tramos'!$I3,0,'A4206 - Tramos'!$I3-C$1),ROW('A4206 - Tramos'!K3)-1) -> 2167949 | D3: =IF( 'A4206 - Tramos'!$I3-D$1>0,OFFSET('A4206 - Tramos'!$I3,0,'A4206 - Tramos'!$I3-D$1),ROW('A4206 - Tramos'!L3)-1) -> 2167956 | E3: =IF( 'A4206 - Tramos'!$I3-E$1>0,OFFSET('A4206 - Tramos'!$I3,0,'A4206 - Tramos'!$I3-E$1),ROW('A4206 - Tramos'!M3)-1) -> 2167963 | F3: =IF( 'A4206 - Tramos'!$I3-F$1>0,OFFSET('A4206 - Tramos'!$I3,0,'A4206 - Tramos'!$I3-F$1),ROW('A4206 - Tramos'!N3)-1) -> 2167970 | G3: =IF( 'A4206 - Tramos'!$I3-G$1>0,OFFSET('A4206 - Tramos'!$I3,0,'A4206 - Tramos'!$I3-G$1),ROW('A4206 - Tramos'!O3)-1) -> 2167977 | H3: =IF( 'A4206 - Tramos'!$I3-H$1>0,OFFSET('A4206 - Tramos'!$I3,0,'A4206 - Tramos'!$I3-H$1),ROW('A4206 - Tramos'!P3)-1) -> 2167984 | ... CW3: =IF( 'A4206 - Tramos'!$I3-CW$1>0,OFFSET('A4206 - Tramos'!$I3,0,'A4206 - Tramos'!$I3-CW$1),ROW('A4206 - Tramos'!DE3)-1) -> 2
A4: =IF( 'A4206 - Tramos'!$I4-A$1>0,OFFSET('A4206 - Tramos'!$I4,0,'A4206 - Tramos'!$I4-A$1),ROW('A4206 - Tramos'!I4)-1) -> 0 | B4: =IF( 'A4206 - Tramos'!$I4-B$1>0,OFFSET('A4206 - Tramos'!$I4,0,'A4206 - Tramos'!$I4-B$1),ROW('A4206 - Tramos'!J4)-1) -> 9249850 | C4: =IF( 'A4206 - Tramos'!$I4-C$1>0,OFFSET('A4206 - Tramos'!$I4,0,'A4206 - Tramos'!$I4-C$1),ROW('A4206 - Tramos'!K4)-1) -> 2167949 | D4: =IF( 'A4206 - Tramos'!$I4-D$1>0,OFFSET('A4206 - Tramos'!$I4,0,'A4206 - Tramos'!$I4-D$1),ROW('A4206 - Tramos'!L4)-1) -> 2167956 | E4: =IF( 'A4206 - Tramos'!$I4-E$1>0,OFFSET('A4206 - Tramos'!$I4,0,'A4206 - Tramos'!$I4-E$1),ROW('A4206 - Tramos'!M4)-1) -> 2167963 | F4: =IF( 'A4206 - Tramos'!$I4-F$1>0,OFFSET('A4206 - Tramos'!$I4,0,'A4206 - Tramos'!$I4-F$1),ROW('A4206 - Tramos'!N4)-1) -> 2167970 | G4: =IF( 'A4206 - Tramos'!$I4-G$1>0,OFFSET('A4206 - Tramos'!$I4,0,'A4206 - Tramos'!$I4-G$1),ROW('A4206 - Tramos'!O4)-1) -> 2167977 | H4: =IF( 'A4206 - Tramos'!$I4-H$1>0,OFFSET('A4206 - Tramos'!$I4,0,'A4206 - Tramos'!$I4-H$1),ROW('A4206 - Tramos'!P4)-1) -> 2167984 | ... CW4: =IF( 'A4206 - Tramos'!$I4-CW$1>0,OFFSET('A4206 - Tramos'!$I4,0,'A4206 - Tramos'!$I4-CW$1),ROW('A4206 - Tramos'!DE4)-1) -> 3
A5: =IF( 'A4206 - Tramos'!$I5-A$1>0,OFFSET('A4206 - Tramos'!$I5,0,'A4206 - Tramos'!$I5-A$1),ROW('A4206 - Tramos'!I5)-1) -> 0 | B5: =IF( 'A4206 - Tramos'!$I5-B$1>0,OFFSET('A4206 - Tramos'!$I5,0,'A4206 - Tramos'!$I5-B$1),ROW('A4206 - Tramos'!J5)-1) -> 9249850 | C5: =IF( 'A4206 - Tramos'!$I5-C$1>0,OFFSET('A4206 - Tramos'!$I5,0,'A4206 - Tramos'!$I5-C$1),ROW('A4206 - Tramos'!K5)-1) -> 2167949 | D5: =IF( 'A4206 - Tramos'!$I5-D$1>0,OFFSET('A4206 - Tramos'!$I5,0,'A4206 - Tramos'!$I5-D$1),ROW('A4206 - Tramos'!L5)-1) -> 2167956 | E5: =IF( 'A4206 - Tramos'!$I5-E$1>0,OFFSET('A4206 - Tramos'!$I5,0,'A4206 - Tramos'!$I5-E$1),ROW('A4206 - Tramos'!M5)-1) -> 2167963 | F5: =IF( 'A4206 - Tramos'!$I5-F$1>0,OFFSET('A4206 - Tramos'!$I5,0,'A4206 - Tramos'!$I5-F$1),ROW('A4206 - Tramos'!N5)-1) -> 2167970 | G5: =IF( 'A4206 - Tramos'!$I5-G$1>0,OFFSET('A4206 - Tramos'!$I5,0,'A4206 - Tramos'!$I5-G$1),ROW('A4206 - Tramos'!O5)-1) -> 2167977 | H5: =IF( 'A4206 - Tramos'!$I5-H$1>0,OFFSET('A4206 - Tramos'!$I5,0,'A4206 - Tramos'!$I5-H$1),ROW('A4206 - Tramos'!P5)-1) -> 2167984 | ... CW5: =IF( 'A4206 - Tramos'!$I5-CW$1>0,OFFSET('A4206 - Tramos'!$I5,0,'A4206 - Tramos'!$I5-CW$1),ROW('A4206 - Tramos'!DE5)-1) -> 4
A6: =IF( 'A4206 - Tramos'!$I6-A$1>0,OFFSET('A4206 - Tramos'!$I6,0,'A4206 - Tramos'!$I6-A$1),ROW('A4206 - Tramos'!I6)-1) -> 0 | B6: =IF( 'A4206 - Tramos'!$I6-B$1>0,OFFSET('A4206 - Tramos'!$I6,0,'A4206 - Tramos'!$I6-B$1),ROW('A4206 - Tramos'!J6)-1) -> 9249850 | C6: =IF( 'A4206 - Tramos'!$I6-C$1>0,OFFSET('A4206 - Tramos'!$I6,0,'A4206 - Tramos'!$I6-C$1),ROW('A4206 - Tramos'!K6)-1) -> 2167949 | D6: =IF( 'A4206 - Tramos'!$I6-D$1>0,OFFSET('A4206 - Tramos'!$I6,0,'A4206 - Tramos'!$I6-D$1),ROW('A4206 - Tramos'!L6)-1) -> 2167956 | E6: =IF( 'A4206 - Tramos'!$I6-E$1>0,OFFSET('A4206 - Tramos'!$I6,0,'A4206 - Tramos'!$I6-E$1),ROW('A4206 - Tramos'!M6)-1) -> 2167963 | F6: =IF( 'A4206 - Tramos'!$I6-F$1>0,OFFSET('A4206 - Tramos'!$I6,0,'A4206 - Tramos'!$I6-F$1),ROW('A4206 - Tramos'!N6)-1) -> 2167970 | G6: =IF( 'A4206 - Tramos'!$I6-G$1>0,OFFSET('A4206 - Tramos'!$I6,0,'A4206 - Tramos'!$I6-G$1),ROW('A4206 - Tramos'!O6)-1) -> 2167977 | H6: =IF( 'A4206 - Tramos'!$I6-H$1>0,OFFSET('A4206 - Tramos'!$I6,0,'A4206 - Tramos'!$I6-H$1),ROW('A4206 - Tramos'!P6)-1) -> 2167984 | ... CW6: =IF( 'A4206 - Tramos'!$I6-CW$1>0,OFFSET('A4206 - Tramos'!$I6,0,'A4206 - Tramos'!$I6-CW$1),ROW('A4206 - Tramos'!DE6)-1) -> 5
A7: =IF( 'A4206 - Tramos'!$I7-A$1>0,OFFSET('A4206 - Tramos'!$I7,0,'A4206 - Tramos'!$I7-A$1),ROW('A4206 - Tramos'!I7)-1) -> 0 | B7: =IF( 'A4206 - Tramos'!$I7-B$1>0,OFFSET('A4206 - Tramos'!$I7,0,'A4206 - Tramos'!$I7-B$1),ROW('A4206 - Tramos'!J7)-1) -> 9249850 | C7: =IF( 'A4206 - Tramos'!$I7-C$1>0,OFFSET('A4206 - Tramos'!$I7,0,'A4206 - Tramos'!$I7-C$1),ROW('A4206 - Tramos'!K7)-1) -> 2167949 | D7: =IF( 'A4206 - Tramos'!$I7-D$1>0,OFFSET('A4206 - Tramos'!$I7,0,'A4206 - Tramos'!$I7-D$1),ROW('A4206 - Tramos'!L7)-1) -> 2167956 | E7: =IF( 'A4206 - Tramos'!$I7-E$1>0,OFFSET('A4206 - Tramos'!$I7,0,'A4206 - Tramos'!$I7-E$1),ROW('A4206 - Tramos'!M7)-1) -> 2167963 | F7: =IF( 'A4206 - Tramos'!$I7-F$1>0,OFFSET('A4206 - Tramos'!$I7,0,'A4206 - Tramos'!$I7-F$1),ROW('A4206 - Tramos'!N7)-1) -> 2167970 | G7: =IF( 'A4206 - Tramos'!$I7-G$1>0,OFFSET('A4206 - Tramos'!$I7,0,'A4206 - Tramos'!$I7-G$1),ROW('A4206 - Tramos'!O7)-1) -> 2167977 | H7: =IF( 'A4206 - Tramos'!$I7-H$1>0,OFFSET('A4206 - Tramos'!$I7,0,'A4206 - Tramos'!$I7-H$1),ROW('A4206 - Tramos'!P7)-1) -> 2167984 | ... CW7: =IF( 'A4206 - Tramos'!$I7-CW$1>0,OFFSET('A4206 - Tramos'!$I7,0,'A4206 - Tramos'!$I7-CW$1),ROW('A4206 - Tramos'!DE7)-1) -> 6
A8: =IF( 'A4206 - Tramos'!$I8-A$1>0,OFFSET('A4206 - Tramos'!$I8,0,'A4206 - Tramos'!$I8-A$1),ROW('A4206 - Tramos'!I8)-1) -> 0 | B8: =IF( 'A4206 - Tramos'!$I8-B$1>0,OFFSET('A4206 - Tramos'!$I8,0,'A4206 - Tramos'!$I8-B$1),ROW('A4206 - Tramos'!J8)-1) -> 9249850 | C8: =IF( 'A4206 - Tramos'!$I8-C$1>0,OFFSET('A4206 - Tramos'!$I8,0,'A4206 - Tramos'!$I8-C$1),ROW('A4206 - Tramos'!K8)-1) -> 2167949 | D8: =IF( 'A4206 - Tramos'!$I8-D$1>0,OFFSET('A4206 - Tramos'!$I8,0,'A4206 - Tramos'!$I8-D$1),ROW('A4206 - Tramos'!L8)-1) -> 2167956 | E8: =IF( 'A4206 - Tramos'!$I8-E$1>0,OFFSET('A4206 - Tramos'!$I8,0,'A4206 - Tramos'!$I8-E$1),ROW('A4206 - Tramos'!M8)-1) -> 2167963 | F8: =IF( 'A4206 - Tramos'!$I8-F$1>0,OFFSET('A4206 - Tramos'!$I8,0,'A4206 - Tramos'!$I8-F$1),ROW('A4206 - Tramos'!N8)-1) -> 2167970 | G8: =IF( 'A4206 - Tramos'!$I8-G$1>0,OFFSET('A4206 - Tramos'!$I8,0,'A4206 - Tramos'!$I8-G$1),ROW('A4206 - Tramos'!O8)-1) -> 2167977 | H8: =IF( 'A4206 - Tramos'!$I8-H$1>0,OFFSET('A4206 - Tramos'!$I8,0,'A4206 - Tramos'!$I8-H$1),ROW('A4206 - Tramos'!P8)-1) -> 2167984 | ... CW8: =IF( 'A4206 - Tramos'!$I8-CW$1>0,OFFSET('A4206 - Tramos'!$I8,0,'A4206 - Tramos'!$I8-CW$1),ROW('A4206 - Tramos'!DE8)-1) -> 7
A9: =IF( 'A4206 - Tramos'!$I9-A$1>0,OFFSET('A4206 - Tramos'!$I9,0,'A4206 - Tramos'!$I9-A$1),ROW('A4206 - Tramos'!I9)-1) -> 0 | B9: =IF( 'A4206 - Tramos'!$I9-B$1>0,OFFSET('A4206 - Tramos'!$I9,0,'A4206 - Tramos'!$I9-B$1),ROW('A4206 - Tramos'!J9)-1) -> 9249850 | C9: =IF( 'A4206 - Tramos'!$I9-C$1>0,OFFSET('A4206 - Tramos'!$I9,0,'A4206 - Tramos'!$I9-C$1),ROW('A4206 - Tramos'!K9)-1) -> 2167949 | D9: =IF( 'A4206 - Tramos'!$I9-D$1>0,OFFSET('A4206 - Tramos'!$I9,0,'A4206 - Tramos'!$I9-D$1),ROW('A4206 - Tramos'!L9)-1) -> 2167956 | E9: =IF( 'A4206 - Tramos'!$I9-E$1>0,OFFSET('A4206 - Tramos'!$I9,0,'A4206 - Tramos'!$I9-E$1),ROW('A4206 - Tramos'!M9)-1) -> 2167963 | F9: =IF( 'A4206 - Tramos'!$I9-F$1>0,OFFSET('A4206 - Tramos'!$I9,0,'A4206 - Tramos'!$I9-F$1),ROW('A4206 - Tramos'!N9)-1) -> 2167970 | G9: =IF( 'A4206 - Tramos'!$I9-G$1>0,OFFSET('A4206 - Tramos'!$I9,0,'A4206 - Tramos'!$I9-G$1),ROW('A4206 - Tramos'!O9)-1) -> 2167977 | H9: =IF( 'A4206 - Tramos'!$I9-H$1>0,OFFSET('A4206 - Tramos'!$I9,0,'A4206 - Tramos'!$I9-H$1),ROW('A4206 - Tramos'!P9)-1) -> 2167984 | ... CW9: =IF( 'A4206 - Tramos'!$I9-CW$1>0,OFFSET('A4206 - Tramos'!$I9,0,'A4206 - Tramos'!$I9-CW$1),ROW('A4206 - Tramos'!DE9)-1) -> 8
A10: =IF( 'A4206 - Tramos'!$I10-A$1>0,OFFSET('A4206 - Tramos'!$I10,0,'A4206 - Tramos'!$I10-A$1),ROW('A4206 - Tramos'!I10)-1) -> 0 | B10: =IF( 'A4206 - Tramos'!$I10-B$1>0,OFFSET('A4206 - Tramos'!$I10,0,'A4206 - Tramos'!$I10-B$1),ROW('A4206 - Tramos'!J10)-1) -> 9249850 | C10: =IF( 'A4206 - Tramos'!$I10-C$1>0,OFFSET('A4206 - Tramos'!$I10,0,'A4206 - Tramos'!$I10-C$1),ROW('A4206 - Tramos'!K10)-1) -> 2167949 | D10: =IF( 'A4206 - Tramos'!$I10-D$1>0,OFFSET('A4206 - Tramos'!$I10,0,'A4206 - Tramos'!$I10-D$1),ROW('A4206 - Tramos'!L10)-1) -> 2167956 | E10: =IF( 'A4206 - Tramos'!$I10-E$1>0,OFFSET('A4206 - Tramos'!$I10,0,'A4206 - Tramos'!$I10-E$1),ROW('A4206 - Tramos'!M10)-1) -> 2167963 | F10: =IF( 'A4206 - Tramos'!$I10-F$1>0,OFFSET('A4206 - Tramos'!$I10,0,'A4206 - Tramos'!$I10-F$1),ROW('A4206 - Tramos'!N10)-1) -> 2167970 | G10: =IF( 'A4206 - Tramos'!$I10-G$1>0,OFFSET('A4206 - Tramos'!$I10,0,'A4206 - Tramos'!$I10-G$1),ROW('A4206 - Tramos'!O10)-1) -> 2167977 | H10: =IF( 'A4206 - Tramos'!$I10-H$1>0,OFFSET('A4206 - Tramos'!$I10,0,'A4206 - Tramos'!$I10-H$1),ROW('A4206 - Tramos'!P10)-1) -> 2167984 | ... CW10: =IF( 'A4206 - Tramos'!$I10-CW$1>0,OFFSET('A4206 - Tramos'!$I10,0,'A4206 - Tramos'!$I10-CW$1),ROW('A4206 - Tramos'!DE10)-1) -> 9
A11: =IF( 'A4206 - Tramos'!$I11-A$1>0,OFFSET('A4206 - Tramos'!$I11,0,'A4206 - Tramos'!$I11-A$1),ROW('A4206 - Tramos'!I11)-1) -> 0 | B11: =IF( 'A4206 - Tramos'!$I11-B$1>0,OFFSET('A4206 - Tramos'!$I11,0,'A4206 - Tramos'!$I11-B$1),ROW('A4206 - Tramos'!J11)-1) -> 9249850 | C11: =IF( 'A4206 - Tramos'!$I11-C$1>0,OFFSET('A4206 - Tramos'!$I11,0,'A4206 - Tramos'!$I11-C$1),ROW('A4206 - Tramos'!K11)-1) -> 2167949 | D11: =IF( 'A4206 - Tramos'!$I11-D$1>0,OFFSET('A4206 - Tramos'!$I11,0,'A4206 - Tramos'!$I11-D$1),ROW('A4206 - Tramos'!L11)-1) -> 2167956 | E11: =IF( 'A4206 - Tramos'!$I11-E$1>0,OFFSET('A4206 - Tramos'!$I11,0,'A4206 - Tramos'!$I11-E$1),ROW('A4206 - Tramos'!M11)-1) -> 2167963 | F11: =IF( 'A4206 - Tramos'!$I11-F$1>0,OFFSET('A4206 - Tramos'!$I11,0,'A4206 - Tramos'!$I11-F$1),ROW('A4206 - Tramos'!N11)-1) -> 2167970 | G11: =IF( 'A4206 - Tramos'!$I11-G$1>0,OFFSET('A4206 - Tramos'!$I11,0,'A4206 - Tramos'!$I11-G$1),ROW('A4206 - Tramos'!O11)-1) -> 2167977 | H11: =IF( 'A4206 - Tramos'!$I11-H$1>0,OFFSET('A4206 - Tramos'!$I11,0,'A4206 - Tramos'!$I11-H$1),ROW('A4206 - Tramos'!P11)-1) -> 2167984 | ... CW11: =IF( 'A4206 - Tramos'!$I11-CW$1>0,OFFSET('A4206 - Tramos'!$I11,0,'A4206 - Tramos'!$I11-CW$1),ROW('A4206 - Tramos'!DE11)-1) -> 10
A12: =IF( 'A4206 - Tramos'!$I12-A$1>0,OFFSET('A4206 - Tramos'!$I12,0,'A4206 - Tramos'!$I12-A$1),ROW('A4206 - Tramos'!I12)-1) -> 0 | B12: =IF( 'A4206 - Tramos'!$I12-B$1>0,OFFSET('A4206 - Tramos'!$I12,0,'A4206 - Tramos'!$I12-B$1),ROW('A4206 - Tramos'!J12)-1) -> 9249850 | C12: =IF( 'A4206 - Tramos'!$I12-C$1>0,OFFSET('A4206 - Tramos'!$I12,0,'A4206 - Tramos'!$I12-C$1),ROW('A4206 - Tramos'!K12)-1) -> 2167949 | D12: =IF( 'A4206 - Tramos'!$I12-D$1>0,OFFSET('A4206 - Tramos'!$I12,0,'A4206 - Tramos'!$I12-D$1),ROW('A4206 - Tramos'!L12)-1) -> 2167956 | E12: =IF( 'A4206 - Tramos'!$I12-E$1>0,OFFSET('A4206 - Tramos'!$I12,0,'A4206 - Tramos'!$I12-E$1),ROW('A4206 - Tramos'!M12)-1) -> 2167963 | F12: =IF( 'A4206 - Tramos'!$I12-F$1>0,OFFSET('A4206 - Tramos'!$I12,0,'A4206 - Tramos'!$I12-F$1),ROW('A4206 - Tramos'!N12)-1) -> 2167970 | G12: =IF( 'A4206 - Tramos'!$I12-G$1>0,OFFSET('A4206 - Tramos'!$I12,0,'A4206 - Tramos'!$I12-G$1),ROW('A4206 - Tramos'!O12)-1) -> 2167977 | H12: =IF( 'A4206 - Tramos'!$I12-H$1>0,OFFSET('A4206 - Tramos'!$I12,0,'A4206 - Tramos'!$I12-H$1),ROW('A4206 - Tramos'!P12)-1) -> 2167984 | ... CW12: =IF( 'A4206 - Tramos'!$I12-CW$1>0,OFFSET('A4206 - Tramos'!$I12,0,'A4206 - Tramos'!$I12-CW$1),ROW('A4206 - Tramos'!DE12)-1) -> 11
A13: =IF( 'A4206 - Tramos'!$I13-A$1>0,OFFSET('A4206 - Tramos'!$I13,0,'A4206 - Tramos'!$I13-A$1),ROW('A4206 - Tramos'!I13)-1) -> 0 | B13: =IF( 'A4206 - Tramos'!$I13-B$1>0,OFFSET('A4206 - Tramos'!$I13,0,'A4206 - Tramos'!$I13-B$1),ROW('A4206 - Tramos'!J13)-1) -> 9249850 | C13: =IF( 'A4206 - Tramos'!$I13-C$1>0,OFFSET('A4206 - Tramos'!$I13,0,'A4206 - Tramos'!$I13-C$1),ROW('A4206 - Tramos'!K13)-1) -> 2167949 | D13: =IF( 'A4206 - Tramos'!$I13-D$1>0,OFFSET('A4206 - Tramos'!$I13,0,'A4206 - Tramos'!$I13-D$1),ROW('A4206 - Tramos'!L13)-1) -> 2167956 | E13: =IF( 'A4206 - Tramos'!$I13-E$1>0,OFFSET('A4206 - Tramos'!$I13,0,'A4206 - Tramos'!$I13-E$1),ROW('A4206 - Tramos'!M13)-1) -> 2167963 | F13: =IF( 'A4206 - Tramos'!$I13-F$1>0,OFFSET('A4206 - Tramos'!$I13,0,'A4206 - Tramos'!$I13-F$1),ROW('A4206 - Tramos'!N13)-1) -> 2167970 | G13: =IF( 'A4206 - Tramos'!$I13-G$1>0,OFFSET('A4206 - Tramos'!$I13,0,'A4206 - Tramos'!$I13-G$1),ROW('A4206 - Tramos'!O13)-1) -> 2167977 | H13: =IF( 'A4206 - Tramos'!$I13-H$1>0,OFFSET('A4206 - Tramos'!$I13,0,'A4206 - Tramos'!$I13-H$1),ROW('A4206 - Tramos'!P13)-1) -> 2167984 | ... CW13: =IF( 'A4206 - Tramos'!$I13-CW$1>0,OFFSET('A4206 - Tramos'!$I13,0,'A4206 - Tramos'!$I13-CW$1),ROW('A4206 - Tramos'!DE13)-1) -> 12
... A54: =IF( 'A4206 - Tramos'!$I54-A$1>0,OFFSET('A4206 - Tramos'!$I54,0,'A4206 - Tramos'!$I54-A$1),ROW('A4206 - Tramos'!I54)-1) -> 0 | B54: =IF( 'A4206 - Tramos'!$I54-B$1>0,OFFSET('A4206 - Tramos'!$I54,0,'A4206 - Tramos'!$I54-B$1),ROW('A4206 - Tramos'!J54)-1) -> 9249850 | C54: =IF( 'A4206 - Tramos'!$I54-C$1>0,OFFSET('A4206 - Tramos'!$I54,0,'A4206 - Tramos'!$I54-C$1),ROW('A4206 - Tramos'!K54)-1) -> 2167949 | D54: =IF( 'A4206 - Tramos'!$I54-D$1>0,OFFSET('A4206 - Tramos'!$I54,0,'A4206 - Tramos'!$I54-D$1),ROW('A4206 - Tramos'!L54)-1) -> 2167956 | E54: =IF( 'A4206 - Tramos'!$I54-E$1>0,OFFSET('A4206 - Tramos'!$I54,0,'A4206 - Tramos'!$I54-E$1),ROW('A4206 - Tramos'!M54)-1) -> 2167963 | F54: =IF( 'A4206 - Tramos'!$I54-F$1>0,OFFSET('A4206 - Tramos'!$I54,0,'A4206 - Tramos'!$I54-F$1),ROW('A4206 - Tramos'!N54)-1) -> 2167970 | G54: =IF( 'A4206 - Tramos'!$I54-G$1>0,OFFSET('A4206 - Tramos'!$I54,0,'A4206 - Tramos'!$I54-G$1),ROW('A4206 - Tramos'!O54)-1) -> 2167977 | H54: =IF( 'A4206 - Tramos'!$I54-H$1>0,OFFSET('A4206 - Tramos'!$I54,0,'A4206 - Tramos'!$I54-H$1),ROW('A4206 - Tramos'!P54)-1) -> 2167984 | ... CW54: =IF( 'A4206 - Tramos'!$I54-CW$1>0,OFFSET('A4206 - Tramos'!$I54,0,'A4206 - Tramos'!$I54-CW$1),ROW('A4206 - Tramos'!DE54)-1) -> 53

Sheet A4206 - Arbol
A1: {=_xlfn.UNIQUE('A4206 - Tramos Ordenados'!A:A)} -> 0 | B1: {=_xlfn.UNIQUE('A4206 - Tramos Ordenados'!B:B)} -> 1 | C1: {=_xlfn.UNIQUE('A4206 - Tramos Ordenados'!C:C)} -> 2 | D1: {=_xlfn.UNIQUE('A4206 - Tramos Ordenados'!D:D)} -> 3 | E1: {=_xlfn.UNIQUE('A4206 - Tramos Ordenados'!E:E)} -> 4 | F1: {=_xlfn.UNIQUE('A4206 - Tramos Ordenados'!F:F)} -> 5 | G1: {=_xlfn.UNIQUE('A4206 - Tramos Ordenados'!G:G)} -> 6 | H1: {=_xlfn.UNIQUE('A4206 - Tramos Ordenados'!H:H)} -> 7 | I1: {=_xlfn.UNIQUE('A4206 - Tramos Ordenados'!I:I)} -> 8 | J1: {=_xlfn.UNIQUE('A4206 - Tramos Ordenados'!J:J)} -> 9 | K1: {=_xlfn.UNIQUE('A4206 - Tramos Ordenados'!K:K)} -> 10 | L1: {=_xlfn.UNIQUE('A4206 - Tramos Ordenados'!L:L)} -> 11 | M1: {=_xlfn.UNIQUE('A4206 - Tramos Ordenados'!M:M)} -> 12 | N1: {=_xlfn.UNIQUE('A4206 - Tramos Ordenados'!N:N)} -> 13 | O1: {=_xlfn.UNIQUE('A4206 - Tramos Ordenados'!O:O)} -> 14 | P1: {=_xlfn.UNIQUE('A4206 - Tramos Ordenados'!P:P)} -> 15 | Q1: {=_xlfn.UNIQUE('A4206 - Tramos Ordenados'!Q:Q)} -> 16 | R1: {=_xlfn.UNIQUE('A4206 - Tramos Ordenados'!R:R)} -> 17 | S1: {=_xlfn.UNIQUE('A4206 - Tramos Ordenados'!S:S)} -> 18 | T1: {=_xlfn.UNIQUE('A4206 - Tramos Ordenados'!T:T)} -> 19 | U1: {=_xlfn.UNIQUE('A4206 - Tramos Ordenados'!U:U)} -> 20 | V1: {=_xlfn.UNIQUE('A4206 - Tramos Ordenados'!V:V)} -> 21 | W1: {=_xlfn.UNIQUE('A4206 - Tramos Ordenados'!W:W)} -> 22 | X1: {=_xlfn.UNIQUE('A4206 - Tramos Ordenados'!X:X)} -> 23 | Y1: {=_xlfn.UNIQUE('A4206 - Tramos Ordenados'!Y:Y)} -> 24 | Z1: {=_xlfn.UNIQUE('A4206 - Tramos Ordenados'!Z:Z)} -> 25 | AA1: {=_xlfn.UNIQUE('A4206 - Tramos Ordenados'!AA:AA)} -> 26 | AB1: {=_xlfn.UNIQUE('A4206 - Tramos Ordenados'!AB:AB)} -> 27 | AC1: {=_xlfn.UNIQUE('A4206 - Tramos Ordenados'!AC:AC)} -> 28 | AD1: {=_xlfn.UNIQUE('A4206 - Tramos Ordenados'!AD:AD)} -> 29 | AE1: {=_xlfn.UNIQUE('A4206 - Tramos Ordenados'!AE:AE)} -> 30 | AF1: {=_xlfn.UNIQUE('A4206 - Tramos Ordenados'!AF:AF)} -> 31 | AG1: {=_xlfn.UNIQUE('A4206 - Tramos Ordenados'!AG:AG)} -> 32 | AH1: {=_xlfn.UNIQUE('A4206 - Tramos Ordenados'!AH:AH)} -> 33 | AI1: {=_xlfn.UNIQUE('A4206 - Tramos Ordenados'!AI:AI)} -> 34 | AJ1: {=_xlfn.UNIQUE('A4206 - Tramos Ordenados'!AJ:AJ)} -> 35 | AK1: {=_xlfn.UNIQUE('A4206 - Tramos Ordenados'!AK:AK)} -> 36 | AL1: {=_xlfn.UNIQUE('A4206 - Tramos Ordenados'!AL:AL)} -> 37 | AM1: {=_xlfn.UNIQUE('A4206 - Tramos Ordenados'!AM:AM)} -> 38 | AN1: {=_xlfn.UNIQUE('A4206 - Tramos Ordenados'!AN:AN)} -> 39 | AO1: {=_xlfn.UNIQUE('A4206 - Tramos Ordenados'!AO:AO)} -> 40 | AP1: {=_xlfn.UNIQUE('A4206 - Tramos Ordenados'!AP:AP)} -> 41 | AQ1: {=_xlfn.UNIQUE('A4206 - Tramos Ordenados'!AQ:AQ)} -> 42 | AR1: {=_xlfn.UNIQUE('A4206 - Tramos Ordenados'!AR:AR)} -> 43 | AS1: {=_xlfn.UNIQUE('A4206 - Tramos Ordenados'!AS:AS)} -> 44 | AT1: {=_xlfn.UNIQUE('A4206 - Tramos Ordenados'!AT:AT)} -> 45 | AU1: {=_xlfn.UNIQUE('A4206 - Tramos Ordenados'!AU:AU)} -> 46 | AV1: {=_xlfn.UNIQUE('A4206 - Tramos Ordenados'!AV:AV)} -> 47 | AW1: {=_xlfn.UNIQUE('A4206 - Tramos Ordenados'!AW:AW)} -> 48 | AX1: {=_xlfn.UNIQUE('A4206 - Tramos Ordenados'!AX:AX)} -> 49 | AY1: {=_xlfn.UNIQUE('A4206 - Tramos Ordenados'!AY:AY)} -> 50 | AZ1: {=_xlfn.UNIQUE('A4206 - Tramos Ordenados'!AZ:AZ)} -> 51 | BA1: {=_xlfn.UNIQUE('A4206 - Tramos Ordenados'!BA:BA)} -> 52 | BB1: {=_xlfn.UNIQUE('A4206 - Tramos Ordenados'!BB:BB)} -> 53 | BC1: {=_xlfn.UNIQUE('A4206 - Tramos Ordenados'!BC:BC)} -> 54 | BD1: {=_xlfn.UNIQUE('A4206 - Tramos Ordenados'!BD:BD)} -> 55 | BE1: {=_xlfn.UNIQUE('A4206 - Tramos Ordenados'!BE:BE)} -> 56 | BF1: {=_xlfn.UNIQUE('A4206 - Tramos Ordenados'!BF:BF)} -> 57 | BG1: {=_xlfn.UNIQUE('A4206 - Tramos Ordenados'!BG:BG)} -> 58 | BH1: {=_xlfn.UNIQUE('A4206 - Tramos Ordenados'!BH:BH)} -> 59 | BI1: {=_xlfn.UNIQUE('A4206 - Tramos Ordenados'!BI:BI)} -> 60 | BJ1: {=_xlfn.UNIQUE('A4206 - Tramos Ordenados'!BJ:BJ)} -> 61 | BK1: {=_xlfn.UNIQUE('A4206 - Tramos Ordenados'!BK:BK)} -> 62 | BL1: {=_xlfn.UNIQUE('A4206 - Tramos Ordenados'!BL:BL)} -> 63 | BM1: {=_xlfn.UNIQUE('A4206 - Tramos Ordenados'!BM:BM)} -> 64 | BN1: {=_xlfn.UNIQUE('A4206 - Tramos Ordenados'!BN:BN)} -> 65 | BO1: {=_xlfn.UNIQUE('A4206 - Tramos Ordenados'!BO:BO)} -> 66 | BP1: {=_xlfn.UNIQUE('A4206 - Tramos Ordenados'!BP:BP)} -> 67 | BQ1: {=_xlfn.UNIQUE('A4206 - Tramos Ordenados'!BQ:BQ)} -> 68 | BR1: {=_xlfn.UNIQUE('A4206 - Tramos Ordenados'!BR:BR)} -> 69 | BS1: {=_xlfn.UNIQUE('A4206 - Tramos Ordenados'!BS:BS)} -> 70 | BT1: {=_xlfn.UNIQUE('A4206 - Tramos Ordenados'!BT:BT)} -> 71 | BU1: {=_xlfn.UNIQUE('A4206 - Tramos Ordenados'!BU:BU)} -> 72 | BV1: {=_xlfn.UNIQUE('A4206 - Tramos Ordenados'!BV:BV)} -> 73 | BW1: {=_xlfn.UNIQUE('A4206 - Tramos Ordenados'!BW:BW)} -> 74 | BX1: {=_xlfn.UNIQUE('A4206 - Tramos Ordenados'!BX:BX)} -> 75 | BY1: {=_xlfn.UNIQUE('A4206 - Tramos Ordenados'!BY:BY)} -> 76 | BZ1: {=_xlfn.UNIQUE('A4206 - Tramos Ordenados'!BZ:BZ)} -> 77 | CA1: {=_xlfn.UNIQUE('A4206 - Tramos Ordenados'!CA:CA)} -> 78 | CB1: {=_xlfn.UNIQUE('A4206 - Tramos Ordenados'!CB:CB)} -> 79 | CC1: {=_xlfn.UNIQUE('A4206 - Tramos Ordenados'!CC:CC)} -> 80 | CD1: {=_xlfn.UNIQUE('A4206 - Tramos Ordenados'!CD:CD)} -> 81 | CE1: {=_xlfn.UNIQUE('A4206 - Tramos Ordenados'!CE:CE)} -> 82 | CF1: {=_xlfn.UNIQUE('A4206 - Tramos Ordenados'!CF:CF)} -> 83 | CG1: {=_xlfn.UNIQUE('A4206 - Tramos Ordenados'!CG:CG)} -> 84 | CH1: {=_xlfn.UNIQUE('A4206 - Tramos Ordenados'!CH:CH)} -> 85 | CI1: {=_xlfn.UNIQUE('A4206 - Tramos Ordenados'!CI:CI)} -> 86 | CJ1: {=_xlfn.UNIQUE('A4206 - Tramos Ordenados'!CJ:CJ)} -> 87 | CK1: {=_xlfn.UNIQUE('A4206 - Tramos Ordenados'!CK:CK)} -> 88 | CL1: {=_xlfn.UNIQUE('A4206 - Tramos Ordenados'!CL:CL)} -> 89 | CM1: {=_xlfn.UNIQUE('A4206 - Tramos Ordenados'!CM:CM)} -> 90 | CN1: {=_xlfn.UNIQUE('A4206 - Tramos Ordenados'!CN:CN)} -> 91 | CO1: {=_xlfn.UNIQUE('A4206 - Tramos Ordenados'!CO:CO)} -> 92 | CP1: {=_xlfn.UNIQUE('A4206 - Tramos Ordenados'!CP:CP)} -> 93 | CQ1: {=_xlfn.UNIQUE('A4206 - Tramos Ordenados'!CQ:CQ)} -> 94 | CR1: {=_xlfn.UNIQUE('A4206 - Tramos Ordenados'!CR:CR)} -> 95 | CS1: {=_xlfn.UNIQUE('A4206 - Tramos Ordenados'!CS:CS)} -> 96 | CT1: {=_xlfn.UNIQUE('A4206 - Tramos Ordenados'!CT:CT)} -> 97 | CU1: {=_xlfn.UNIQUE('A4206 - Tramos Ordenados'!CU:CU)} -> 98 | CV1: {=_xlfn.UNIQUE('A4206 - Tramos Ordenados'!CV:CV)} -> 99 | CW1: {=_xlfn.UNIQUE('A4206 - Tramos Ordenados'!CW:CW)} -> 100
A2: 0 | B2: 9249850 | C2: 2167949 | D2: 2167956 | E2: 2167963 | F2: 2167970 | G2: 2167977 | H2: 2167984 | I2: 7869054 | J2: 7869061 | K2: 1 | L2: 1 | M2: 1 | N2: 1 | O2: 1 | P2: 1 | Q2: 1 | R2: 1 | S2: 1 | T2: 1 | U2: 1 | V2: 1 | W2: 1 | X2: 1 | Y2: 1 | Z2: 1 | AA2: 1 | AB2: 1 | AC2: 1 | AD2: 1 | AE2: 1 | AF2: 1 | AG2: 1 | AH2: 1 | AI2: 1 | AJ2: 1 | AK2: 1 | AL2: 1 | AM2: 1 | AN2: 1 | AO2: 1 | AP2: 1 | AQ2: 1 | AR2: 1 | AS2: 1 | AT2: 1 | AU2: 1 | AV2: 1 | AW2: 1 | AX2: 1 | AY2: 1 | AZ2: 1 | BA2: 1 | BB2: 1 | BC2: 1 | BD2: 1 | BE2: 1 | BF2: 1 | BG2: 1 | BH2: 1 | BI2: 1 | BJ2: 1 | BK2: 1 | BL2: 1 | BM2: 1 | BN2: 1 | BO2: 1 | BP2: 1 | BQ2: 1 | BR2: 1 | BS2: 1 | BT2: 1 | BU2: 1 | BV2: 1 | BW2: 1 | BX2: 1 | BY2: 1 | BZ2: 1 | CA2: 1 | CB2: 1 | CC2: 1 | CD2: 1 | CE2: 1 | CF2: 1 | CG2: 1 | CH2: 1 | CI2: 1 | CJ2: 1 | CK2: 1 | CL2: 1 | CM2: 1 | CN2: 1 | CO2: 1 | CP2: 1 | CQ2: 1 | CR2: 1 | CS2: 1 | CT2: 1 | CU2: 1 | CV2: 1 | CW2: 1
B3: 0 | C3: 0 | D3: 0 | E3: 0 | F3: 0 | G3: 0 | H3: 0 | I3: 0 | J3: 2167991 | K3: 2167998 | L3: 2168005 | M3: 2168012 | N3: 2168019 | O3: 9250025 | P3: 9250030 | Q3: 9250035 | R3: 9250040 | S3: 9250045 | T3: 2168026 | U3: 2168033 | V3: 2168047 | W3: 2168040 | X3: 2 | Y3: 2 | Z3: 2 | AA3: 2 | AB3: 2 | AC3: 2 | AD3: 2 | AE3: 2 | AF3: 2 | AG3: 2 | AH3: 2 | AI3: 2 | AJ3: 2 | AK3: 2 | AL3: 2 | AM3: 2 | AN3: 2 | AO3: 2 | AP3: 2 | AQ3: 2 | AR3: 2 | AS3: 2 | AT3: 2 | AU3: 2 | AV3: 2 | AW3: 2 | AX3: 2 | AY3: 2 | AZ3: 2 | BA3: 2 | BB3: 2 | BC3: 2 | BD3: 2 | BE3: 2 | BF3: 2 | BG3: 2 | BH3: 2 | BI3: 2 | BJ3: 2 | BK3: 2 | BL3: 2 | BM3: 2 | BN3: 2 | BO3: 2 | BP3: 2 | BQ3: 2 | BR3: 2 | BS3: 2 | BT3: 2 | BU3: 2 | BV3: 2 | BW3: 2 | BX3: 2 | BY3: 2 | BZ3: 2 | CA3: 2 | CB3: 2 | CC3: 2 | CD3: 2 | CE3: 2 | CF3: 2 | CG3: 2 | CH3: 2 | CI3: 2 | CJ3: 2 | CK3: 2 | CL3: 2 | CM3: 2 | CN3: 2 | CO3: 2 | CP3: 2 | CQ3: 2 | CR3: 2 | CS3: 2 | CT3: 2 | CU3: 2 | CV3: 2 | CW3: 2
J4: 0 | K4: 0 | L4: 0 | M4: 0 | N4: 0 | O4: 0 | P4: 0 | Q4: 0 | R4: 0 | S4: 0 | T4: 0 | U4: 0 | V4: 0 | W4: 2168054 | X4: 2168061 | Y4: 2168068 | Z4: 2168075 | AA4: 2150842 | AB4: 2150828 | AC4: 3 | AD4: 3 | AE4: 3 | AF4: 3 | AG4: 3 | AH4: 3 | AI4: 3 | AJ4: 3 | AK4: 3 | AL4: 3 | AM4: 3 | AN4: 3 | AO4: 3 | AP4: 3 | AQ4: 3 | AR4: 3 | AS4: 3 | AT4: 3 | AU4: 3 | AV4: 3 | AW4: 3 | AX4: 3 | AY4: 3 | AZ4: 3 | BA4: 3 | BB4: 3 | BC4: 3 | BD4: 3 | BE4: 3 | BF4: 3 | BG4: 3 | BH4: 3 | BI4: 3 | BJ4: 3 | BK4: 3 | BL4: 3 | BM4: 3 | BN4: 3 | BO4: 3 | BP4: 3 | BQ4: 3 | BR4: 3 | BS4: 3 | BT4: 3 | BU4: 3 | BV4: 3 | BW4: 3 | BX4: 3 | BY4: 3 | BZ4: 3 | CA4: 3 | CB4: 3 | CC4: 3 | CD4: 3 | CE4: 3 | CF4: 3 | CG4: 3 | CH4: 3 | CI4: 3 | CJ4: 3 | CK4: 3 | CL4: 3 | CM4: 3 | CN4: 3 | CO4: 3 | CP4: 3 | CQ4: 3 | CR4: 3 | CS4: 3 | CT4: 3 | CU4: 3 | CV4: 3 | CW4: 3
W5: 0 | X5: 0 | Y5: 0 | Z5: 0 | AA5: 0 | AB5: 2150835 | AC5: 2168082 | AD5: 2168089 | AE5: 2168096 | AF5: 2132688 | AG5: 2132681 | AH5: 4 | AI5: 4 | AJ5: 4 | AK5: 4 | AL5: 4 | AM5: 4 | AN5: 4 | AO5: 4 | AP5: 4 | AQ5: 4 | AR5: 4 | AS5: 4 | AT5: 4 | AU5: 4 | AV5: 4 | AW5: 4 | AX5: 4 | AY5: 4 | AZ5: 4 | BA5: 4 | BB5: 4 | BC5: 4 | BD5: 4 | BE5: 4 | BF5: 4 | BG5: 4 | BH5: 4 | BI5: 4 | BJ5: 4 | BK5: 4 | BL5: 4 | BM5: 4 | BN5: 4 | BO5: 4 | BP5: 4 | BQ5: 4 | BR5: 4 | BS5: 4 | BT5: 4 | BU5: 4 | BV5: 4 | BW5: 4 | BX5: 4 | BY5: 4 | BZ5: 4 | CA5: 4 | CB5: 4 | CC5: 4 | CD5: 4 | CE5: 4 | CF5: 4 | CG5: 4 | CH5: 4 | CI5: 4 | CJ5: 4 | CK5: 4 | CL5: 4 | CM5: 4 | CN5: 4 | CO5: 4 | CP5: 4 | CQ5: 4 | CR5: 4 | CS5: 4 | CT5: 4 | CU5: 4 | CV5: 4 | CW5: 4
AB6: 0 | AC6: 0 | AD6: 0 | AE6: 0 | AF6: 0 | AG6: 2132674 | AH6: 2132660 | AI6: 2132653 | AJ6: 5 | AK6: 5 | AL6: 5 | AM6: 5 | AN6: 5 | AO6: 5 | AP6: 5 | AQ6: 5 | AR6: 5 | AS6: 5 | AT6: 5 | AU6: 5 | AV6: 5 | AW6: 5 | AX6: 5 | AY6: 5 | AZ6: 5 | BA6: 5 | BB6: 5 | BC6: 5 | BD6: 5 | BE6: 5 | BF6: 5 | BG6: 5 | BH6: 5 | BI6: 5 | BJ6: 5 | BK6: 5 | BL6: 5 | BM6: 5 | BN6: 5 | BO6: 5 | BP6: 5 | BQ6: 5 | BR6: 5 | BS6: 5 | BT6: 5 | BU6: 5 | BV6: 5 | BW6: 5 | BX6: 5 | BY6: 5 | BZ6: 5 | CA6: 5 | CB6: 5 | CC6: 5 | CD6: 5 | CE6: 5 | CF6: 5 | CG6: 5 | CH6: 5 | CI6: 5 | CJ6: 5 | CK6: 5 | CL6: 5 | CM6: 5 | CN6: 5 | CO6: 5 | CP6: 5 | CQ6: 5 | CR6: 5 | CS6: 5 | CT6: 5 | CU6: 5 | CV6: 5 | CW6: 5
AG7: 2132667 | AH7: 2168103 | AI7: 2132417 | AJ7: 2132410 | AK7: 2168110 | AL7: 2168117 | AM7: 2168124 | AN7: 2168131 | AO7: 2168138 | AP7: 2131940 | AQ7: 6 | AR7: 6 | AS7: 6 | AT7: 6 | AU7: 6 | AV7: 6 | AW7: 6 | AX7: 6 | AY7: 6 | AZ7: 6 | BA7: 6 | BB7: 6 | BC7: 6 | BD7: 6 | BE7: 6 | BF7: 6 | BG7: 6 | BH7: 6 | BI7: 6 | BJ7: 6 | BK7: 6 | BL7: 6 | BM7: 6 | BN7: 6 | BO7: 6 | BP7: 6 | BQ7: 6 | BR7: 6 | BS7: 6 | BT7: 6 | BU7: 6 | BV7: 6 | BW7: 6 | BX7: 6 | BY7: 6 | BZ7: 6 | CA7: 6 | CB7: 6 | CC7: 6 | CD7: 6 | CE7: 6 | CF7: 6 | CG7: 6 | CH7: 6 | CI7: 6 | CJ7: 6 | CK7: 6 | CL7: 6 | CM7: 6 | CN7: 6 | CO7: 6 | CP7: 6 | CQ7: 6 | CR7: 6 | CS7: 6 | CT7: 6 | CU7: 6 | CV7: 6 | CW7: 6
AG8: 0 | AH8: 0 | AI8: 0 | AJ8: 0 | AK8: 0 | AL8: 0 | AM8: 0 | AN8: 0 | AO8: 0 | AP8: 2168145 | AQ8: 2168152 | AR8: 2168159 | AS8: 2168166 | AT8: 2168173 | AU8: 7 | AV8: 7 | AW8: 7 | AX8: 7 | AY8: 7 | AZ8: 7 | BA8: 7 | BB8: 7 | BC8: 7 | BD8: 7 | BE8: 7 | BF8: 7 | BG8: 7 | BH8: 7 | BI8: 7 | BJ8: 7 | BK8: 7 | BL8: 7 | BM8: 7 | BN8: 7 | BO8: 7 | BP8: 7 | BQ8: 7 | BR8: 7 | BS8: 7 | BT8: 7 | BU8: 7 | BV8: 7 | BW8: 7 | BX8: 7 | BY8: 7 | BZ8: 7 | CA8: 7 | CB8: 7 | CC8: 7 | CD8: 7 | CE8: 7 | CF8: 7 | CG8: 7 | CH8: 7 | CI8: 7 | CJ8: 7 | CK8: 7 | CL8: 7 | CM8: 7 | CN8: 7 | CO8: 7 | CP8: 7 | CQ8: 7 | CR8: 7 | CS8: 7 | CT8: 7 | CU8: 7 | CV8: 7 | CW8: 7
AP9: 0 | AQ9: 0 | AR9: 0 | AS9: 0 | AT9: 2168180 | AU9: 2168187 | AV9: 2168194 | AW9: 2168201 | AX9: 2166407 | AY9: 2168215 | AZ9: 2168208 | BA9: 2168222 | BB9: 2168229 | BC9: 2168236 | BD9: 2149739 | BE9: 2149725 | BF9: 8 | BG9: 8 | BH9: 8 | BI9: 8 | BJ9: 8 | BK9: 8 | BL9: 8 | BM9: 8 | BN9: 8 | BO9: 8 | BP9: 8 | BQ9: 8 | BR9: 8 | BS9: 8 | BT9: 8 | BU9: 8 | BV9: 8 | BW9: 8 | BX9: 8 | BY9: 8 | BZ9: 8 | CA9: 8 | CB9: 8 | CC9: 8 | CD9: 8 | CE9: 8 | CF9: 8 | CG9: 8 | CH9: 8 | CI9: 8 | CJ9: 8 | CK9: 8 | CL9: 8 | CM9: 8 | CN9: 8 | CO9: 8 | CP9: 8 | CQ9: 8 | CR9: 8 | CS9: 8 | CT9: 8 | CU9: 8 | CV9: 8 | CW9: 8
AT10: 0 | AU10: 0 | AV10: 0 | AW10: 0 | AX10: 2165177 | AY10: 19099438 | AZ10: 2165170 | BA10: 2164995 | BB10: 2130236 | BC10: 2130229 | BD10: 2166400 | BE10: 2149711 | BF10: 2149697 | BG10: 2149690 | BH10: 2149683 | BI10: 9 | BJ10: 9 | BK10: 9 | BL10: 9 | BM10: 9 | BN10: 9 | BO10: 9 | BP10: 9 | BQ10: 9 | BR10: 9 | BS10: 9 | BT10: 9 | BU10: 9 | BV10: 9 | BW10: 9 | BX10: 9 | BY10: 9 | BZ10: 9 | CA10: 9 | CB10: 9 | CC10: 9 | CD10: 9 | CE10: 9 | CF10: 9 | CG10: 9 | CH10: 9 | CI10: 9 | CJ10: 9 | CK10: 9 | CL10: 9 | CM10: 9 | CN10: 9 | CO10: 9 | CP10: 9 | CQ10: 9 | CR10: 9 | CS10: 9 | CT10: 9 | CU10: 9 | CV10: 9 | CW10: 9
AX11: 0 | AY11: 0 | AZ11: 0 | BA11: 0 | BB11: 0 | BC11: 2168243 | BD11: 2168250 | BE11: 2149732 | BF11: 7568364 | BG11: 9357140 | BH11: 9357147 | BI11: 10 | BJ11: 10 | BK11: 10 | BL11: 10 | BM11: 10 | BN11: 10 | BO11: 10 | BP11: 10 | BQ11: 10 | BR11: 10 | BS11: 10 | BT11: 10 | BU11: 10 | BV11: 10 | BW11: 10 | BX11: 10 | BY11: 10 | BZ11: 10 | CA11: 10 | CB11: 10 | CC11: 10 | CD11: 10 | CE11: 10 | CF11: 10 | CG11: 10 | CH11: 10 | CI11: 10 | CJ11: 10 | CK11: 10 | CL11: 10 | CM11: 10 | CN11: 10 | CO11: 10 | CP11: 10 | CQ11: 10 | CR11: 10 | CS11: 10 | CT11: 10 | CU11: 10 | CV11: 10 | CW11: 10
BC12: 0 | BD12: 0 | BE12: 2166393 | BF12: 2363719 | BG12: 2343087 | BH12: 2149676 | BI12: 2149669 | BJ12: 11 | BK12: 11 | BL12: 11 | BM12: 11 | BN12: 11 | BO12: 11 | BP12: 11 | BQ12: 11 | BR12: 11 | BS12: 11 | BT12: 11 | BU12: 11 | BV12: 11 | BW12: 11 | BX12: 11 | BY12: 11 | BZ12: 11 | CA12: 11 | CB12: 11 | CC12: 11 | CD12: 11 | CE12: 11 | CF12: 11 | CG12: 11 | CH12: 11 | CI12: 11 | CJ12: 11 | CK12: 11 | CL12: 11 | CM12: 11 | CN12: 11 | CO12: 11 | CP12: 11 | CQ12: 11 | CR12: 11 | CS12: 11 | CT12: 11 | CU12: 11 | CV12: 11 | CW12: 11
BE13: 2168257 | BF13: 2216843 | BG13: 2216836 | BH13: 2343073 | BI13: 2363051 | BJ13: 12 | BK13: 12 | BL13: 12 | BM13: 12 | BN13: 12 | BO13: 12 | BP13: 12 | BQ13: 12 | BR13: 12 | BS13: 12 | BT13: 12 | BU13: 12 | BV13: 12 | BW13: 12 | BX13: 12 | BY13: 12 | BZ13: 12 | CA13: 12 | CB13: 12 | CC13: 12 | CD13: 12 | CE13: 12 | CF13: 12 | CG13: 12 | CH13: 12 | CI13: 12 | CJ13: 12 | CK13: 12 | CL13: 12 | CM13: 12 | CN13: 12 | CO13: 12 | CP13: 12 | CQ13: 12 | CR13: 12 | CS13: 12 | CT13: 12 | CU13: 12 | CV13: 12 | CW13: 12
BE14: 0 | BF14: 2216829 | BG14: 2216822 | BH14: 33490 | BI14: 33474 | BJ14: 13 | BK14: 13 | BL14: 13 | BM14: 13 | BN14: 13 | BO14: 13 | BP14: 13 | BQ14: 13 | BR14: 13 | BS14: 13 | BT14: 13 | BU14: 13 | BV14: 13 | BW14: 13 | BX14: 13 | BY14: 13 | BZ14: 13 | CA14: 13 | CB14: 13 | CC14: 13 | CD14: 13 | CE14: 13 | CF14: 13 | CG14: 13 | CH14: 13 | CI14: 13 | CJ14: 13 | CK14: 13 | CL14: 13 | CM14: 13 | CN14: 13 | CO14: 13 | CP14: 13 | CQ14: 13 | CR14: 13 | CS14: 13 | CT14: 13 | CU14: 13 | CV14: 13 | CW14: 13
BF15: 2216850 | BG15: 2216857 | BH15: 2216815 | BI15: 2115623 | BJ15: 9206685 | BK15: 2115609 | BL15: 14 | BM15: 14 | BN15: 14 | BO15: 14 | BP15: 14 | BQ15: 14 | BR15: 14 | BS15: 14 | BT15: 14 | BU15: 14 | BV15: 14 | BW15: 14 | BX15: 14 | BY15: 14 | BZ15: 14 | CA15: 14 | CB15: 14 | CC15: 14 | CD15: 14 | CE15: 14 | CF15: 14 | CG15: 14 | CH15: 14 | CI15: 14 | CJ15: 14 | CK15: 14 | CL15: 14 | CM15: 14 | CN15: 14 | CO15: 14 | CP15: 14 | CQ15: 14 | CR15: 14 | CS15: 14 | CT15: 14 | CU15: 14 | CV15: 14 | CW15: 14
BF16: 0 | BG16: 0 | BH16: 2216864 | BI16: 2216871 | BJ16: 2342657 | BK16: 2150014 | BL16: 15 | BM16: 15 | BN16: 15 | BO16: 15 | BP16: 15 | BQ16: 15 | BR16: 15 | BS16: 15 | BT16: 15 | BU16: 15 | BV16: 15 | BW16: 15 | BX16: 15 | BY16: 15 | BZ16: 15 | CA16: 15 | CB16: 15 | CC16: 15 | CD16: 15 | CE16: 15 | CF16: 15 | CG16: 15 | CH16: 15 | CI16: 15 | CJ16: 15 | CK16: 15 | CL16: 15 | CM16: 15 | CN16: 15 | CO16: 15 | CP16: 15 | CQ16: 15 | CR16: 15 | CS16: 15 | CT16: 15 | CU16: 15 | CV16: 15 | CW16: 15
BH17: 0 | BI17: 0 | BJ17: 0 | BK17: 2115616 | BL17: 2216808 | BM17: 2133124 | BN17: 2133117 | BO17: 2133110 | BP17: 16 | BQ17: 16 | BR17: 16 | BS17: 16 | BT17: 16 | BU17: 16 | BV17: 16 | BW17: 16 | BX17: 16 | BY17: 16 | BZ17: 16 | CA17: 16 | CB17: 16 | CC17: 16 | CD17: 16 | CE17: 16 | CF17: 16 | CG17: 16 | CH17: 16 | CI17: 16 | CJ17: 16 | CK17: 16 | CL17: 16 | CM17: 16 | CN17: 16 | CO17: 16 | CP17: 16 | CQ17: 16 | CR17: 16 | CS17: 16 | CT17: 16 | CU17: 16 | CV17: 16 | CW17: 16
BK18: 2342664 | BL18: 2342671 | BM18: 2342319 | BN18: 19286334 | BO18: 2342326 | BP18: 2198786 | BQ18: 17 | BR18: 17 | BS18: 17 | BT18: 17 | BU18: 17 | BV18: 17 | BW18: 17 | BX18: 17 | BY18: 17 | BZ18: 17 | CA18: 17 | CB18: 17 | CC18: 17 | CD18: 17 | CE18: 17 | CF18: 17 | CG18: 17 | CH18: 17 | CI18: 17 | CJ18: 17 | CK18: 17 | CL18: 17 | CM18: 17 | CN18: 17 | CO18: 17 | CP18: 17 | CQ18: 17 | CR18: 17 | CS18: 17 | CT18: 17 | CU18: 17 | CV18: 17 | CW18: 17
BK19: 0 | BL19: 2133346 | BM19: 2363454 | BN19: 2363447 | BO19: 2164481 | BP19: 19286327 | BQ19: 2342333 | BR19: 2149151 | BS19: 2218130 | BT19: 18 | BU19: 18 | BV19: 18 | BW19: 18 | BX19: 18 | BY19: 18 | BZ19: 18 | CA19: 18 | CB19: 18 | CC19: 18 | CD19: 18 | CE19: 18 | CF19: 18 | CG19: 18 | CH19: 18 | CI19: 18 | CJ19: 18 | CK19: 18 | CL19: 18 | CM19: 18 | CN19: 18 | CO19: 18 | CP19: 18 | CQ19: 18 | CR19: 18 | CS19: 18 | CT19: 18 | CU19: 18 | CV19: 18 | CW19: 18
BL20: 0 | BM20: 0 | BN20: 0 | BO20: 0 | BP20: 7886277 | BQ20: 7886284 | BR20: 7886291 | BS20: 8647395 | BT20: 19 | BU20: 19 | BV20: 19 | BW20: 19 | BX20: 19 | BY20: 19 | BZ20: 19 | CA20: 19 | CB20: 19 | CC20: 19 | CD20: 19 | CE20: 19 | CF20: 19 | CG20: 19 | CH20: 19 | CI20: 19 | CJ20: 19 | CK20: 19 | CL20: 19 | CM20: 19 | CN20: 19 | CO20: 19 | CP20: 19 | CQ20: 19 | CR20: 19 | CS20: 19 | CT20: 19 | CU20: 19 | CV20: 19 | CW20: 19
BP21: 8647388 | BQ21: 2272452 | BR21: 2236619 | BS21: 19286313 | BT21: 2272438 | BU21: 2250804 | BV21: 20 | BW21: 20 | BX21: 20 | BY21: 20 | BZ21: 20 | CA21: 20 | CB21: 20 | CC21: 20 | CD21: 20 | CE21: 20 | CF21: 20 | CG21: 20 | CH21: 20 | CI21: 20 | CJ21: 20 | CK21: 20 | CL21: 20 | CM21: 20 | CN21: 20 | CO21: 20 | CP21: 20 | CQ21: 20 | CR21: 20 | CS21: 20 | CT21: 20 | CU21: 20 | CV21: 20 | CW21: 20
BP22: 0 | BQ22: 0 | BR22: 2272445 | BS22: 2099370 | BT22: 8368957 | BU22: 8368964 | BV22: 21 | BW22: 21 | BX22: 21 | BY22: 21 | BZ22: 21 | CA22: 21 | CB22: 21 | CC22: 21 | CD22: 21 | CE22: 21 | CF22: 21 | CG22: 21 | CH22: 21 | CI22: 21 | CJ22: 21 | CK22: 21 | CL22: 21 | CM22: 21 | CN22: 21 | CO22: 21 | CP22: 21 | CQ22: 21 | CR22: 21 | CS22: 21 | CT22: 21 | CU22: 21 | CV22: 21 | CW22: 21
BR23: 0 | BS23: 7886298 | BT23: 9348162 | BU23: 9348167 | BV23: 22 | BW23: 22 | BX23: 22 | BY23: 22 | BZ23: 22 | CA23: 22 | CB23: 22 | CC23: 22 | CD23: 22 | CE23: 22 | CF23: 22 | CG23: 22 | CH23: 22 | CI23: 22 | CJ23: 22 | CK23: 22 | CL23: 22 | CM23: 22 | CN23: 22 | CO23: 22 | CP23: 22 | CQ23: 22 | CR23: 22 | CS23: 22 | CT23: 22 | CU23: 22 | CV23: 22 | CW23: 22
BS24: 7090176 | BT24: 2149144 | BU24: 2149137 | BV24: 2149123 | BW24: 23 | BX24: 23 | BY24: 23 | BZ24: 23 | CA24: 23 | CB24: 23 | CC24: 23 | CD24: 23 | CE24: 23 | CF24: 23 | CG24: 23 | CH24: 23 | CI24: 23 | CJ24: 23 | CK24: 23 | CL24: 23 | CM24: 23 | CN24: 23 | CO24: 23 | CP24: 23 | CQ24: 23 | CR24: 23 | CS24: 23 | CT24: 23 | CU24: 23 | CV24: 23 | CW24: 23
BS25: 2218137 | BT25: 8368971 | BU25: 33652 | BV25: 2235823 | BW25: 8042766 | BX25: 7920897 | BY25: 24 | BZ25: 24 | CA25: 24 | CB25: 24 | CC25: 24 | CD25: 24 | CE25: 24 | CF25: 24 | CG25: 24 | CH25: 24 | CI25: 24 | CJ25: 24 | CK25: 24 | CL25: 24 | CM25: 24 | CN25: 24 | CO25: 24 | CP25: 24 | CQ25: 24 | CR25: 24 | CS25: 24 | CT25: 24 | CU25: 24 | CV25: 24 | CW25: 24
BS26: 0 | BT26: 2271646 | BU26: 2164769 | BV26: 19491732 | BW26: 2164762 | BX26: 2164748 | BY26: 2164741 | BZ26: 2164734 | CA26: 25 | CB26: 25 | CC26: 25 | CD26: 25 | CE26: 25 | CF26: 25 | CG26: 25 | CH26: 25 | CI26: 25 | CJ26: 25 | CK26: 25 | CL26: 25 | CM26: 25 | CN26: 25 | CO26: 25 | CP26: 25 | CQ26: 25 | CR26: 25 | CS26: 25 | CT26: 25 | CU26: 25 | CV26: 25 | CW26: 25
BT27: 0 | BU27: 0 | BV27: 2149130 | BW27: 7090183 | BX27: 2342773 | BY27: 2342766 | BZ27: 2342750 | CA27: 26 | CB27: 26 | CC27: 26 | CD27: 26 | CE27: 26 | CF27: 26 | CG27: 26 | CH27: 26 | CI27: 26 | CJ27: 26 | CK27: 26 | CL27: 26 | CM27: 26 | CN27: 26 | CO27: 26 | CP27: 26 | CQ27: 26 | CR27: 26 | CS27: 26 | CT27: 26 | CU27: 26 | CV27: 26 | CW27: 26
BV28: 0 | BW28: 19491724 | BX28: 2236535 | BY28: 9356480 | BZ28: 9245198 | CA28: 27 | CB28: 27 | CC28: 27 | CD28: 27 | CE28: 27 | CF28: 27 | CG28: 27 | CH28: 27 | CI28: 27 | CJ28: 27 | CK28: 27 | CL28: 27 | CM28: 27 | CN28: 27 | CO28: 27 | CP28: 27 | CQ28: 27 | CR28: 27 | CS28: 27 | CT28: 27 | CU28: 27 | CV28: 27 | CW28: 27
BW29: 9249250 | BX29: 9249245 | BY29: 2236528 | BZ29: 2149634 | CA29: 33659 | CB29: 2149620 | CC29: 2149613 | CD29: 28 | CE29: 28 | CF29: 28 | CG29: 28 | CH29: 28 | CI29: 28 | CJ29: 28 | CK29: 28 | CL29: 28 | CM29: 28 | CN29: 28 | CO29: 28 | CP29: 28 | CQ29: 28 | CR29: 28 | CS29: 28 | CT29: 28 | CU29: 28 | CV29: 28 | CW29: 28
BW30: 0 | BX30: 0 | BY30: 9249240 | BZ30: 2271639 | CA30: 2271632 | CB30: 2342803 | CC30: 2342796 | CD30: 2251368 | CE30: 2253557 | CF30: 29 | CG30: 29 | CH30: 29 | CI30: 29 | CJ30: 29 | CK30: 29 | CL30: 29 | CM30: 29 | CN30: 29 | CO30: 29 | CP30: 29 | CQ30: 29 | CR30: 29 | CS30: 29 | CT30: 29 | CU30: 29 | CV30: 29 | CW30: 29
BY31: 0 | BZ31: 2149627 | CA31: 2198646 | CB31: 2164488 | CC31: 2363172 | CD31: 2342826 | CE31: 2271618 | CF31: 2148913 | CG31: 2148892 | CH31: 30 | CI31: 30 | CJ31: 30 | CK31: 30 | CL31: 30 | CM31: 30 | CN31: 30 | CO31: 30 | CP31: 30 | CQ31: 30 | CR31: 30 | CS31: 30 | CT31: 30 | CU31: 30 | CV31: 30 | CW31: 30
BZ32: 9249235 | CA32: 9249230 | CB32: 19286320 | CC32: 2198639 | CD32: 2251346 | CE32: 2167655 | CF32: 2167634 | CG32: 2167627 | CH32: 31 | CI32: 31 | CJ32: 31 | CK32: 31 | CL32: 31 | CM32: 31 | CN32: 31 | CO32: 31 | CP32: 31 | CQ32: 31 | CR32: 31 | CS32: 31 | CT32: 31 | CU32: 31 | CV32: 31 | CW32: 31
BZ33: 0 | CA33: 0 | CB33: 9249225 | CC33: 9249220 | CD33: 2342715 | CE33: 2251339 | CF33: 2251332 | CG33: 2237147 | CH33: 32 | CI33: 32 | CJ33: 32 | CK33: 32 | CL33: 32 | CM33: 32 | CN33: 32 | CO33: 32 | CP33: 32 | CQ33: 32 | CR33: 32 | CS33: 32 | CT33: 32 | CU33: 32 | CV33: 32 | CW33: 32
CB34: 0 | CC34: 0 | CD34: 2342685 | CE34: 2342699 | CF34: 2182868 | CG34: 2182861 | CH34: 2182854 | CI34: 33 | CJ34: 33 | CK34: 33 | CL34: 33 | CM34: 33 | CN34: 33 | CO34: 33 | CP34: 33 | CQ34: 33 | CR34: 33 | CS34: 33 | CT34: 33 | CU34: 33 | CV34: 33 | CW34: 33
CD35: 9249215 | CE35: 2252970 | CF35: 2252963 | CG35: 2251325 | CH35: 2251318 | CI35: 34 | CJ35: 34 | CK35: 34 | CL35: 34 | CM35: 34 | CN35: 34 | CO35: 34 | CP35: 34 | CQ35: 34 | CR35: 34 | CS35: 34 | CT35: 34 | CU35: 34 | CV35: 34 | CW35: 34
CD36: 0 | CE36: 9249210 | CF36: 2167641 | CG36: 31421 | CH36: 31414 | CI36: 35 | CJ36: 35 | CK36: 35 | CL36: 35 | CM36: 35 | CN36: 35 | CO36: 35 | CP36: 35 | CQ36: 35 | CR36: 35 | CS36: 35 | CT36: 35 | CU36: 35 | CV36: 35 | CW36: 35
CE37: 0 | CF37: 2167648 | CG37: 2148906 | CH37: 2253026 | CI37: 2253458 | CJ37: 36 | CK37: 36 | CL37: 36 | CM37: 36 | CN37: 36 | CO37: 36 | CP37: 36 | CQ37: 36 | CR37: 36 | CS37: 36 | CT37: 36 | CU37: 36 | CV37: 36 | CW37: 36
CF38: 9249205 | CG38: 2363165 | CH38: 2342847 | CI38: 2149228 | CJ38: 2149214 | CK38: 37 | CL38: 37 | CM38: 37 | CN38: 37 | CO38: 37 | CP38: 37 | CQ38: 37 | CR38: 37 | CS38: 37 | CT38: 37 | CU38: 37 | CV38: 37 | CW38: 37
CF39: 0 | CG39: 2078376 | CH39: 2078369 | CI39: 8807450 | CJ39: 9350347 | CK39: 38 | CL39: 38 | CM39: 38 | CN39: 38 | CO39: 38 | CP39: 38 | CQ39: 38 | CR39: 38 | CS39: 38 | CT39: 38 | CU39: 38 | CV39: 38 | CW39: 38
CG40: 9249200 | CH40: 9249195 | CI40: 2078362 | CJ40: 2078355 | CK40: 2078334 | CL40: 39 | CM40: 39 | CN40: 39 | CO40: 39 | CP40: 39 | CQ40: 39 | CR40: 39 | CS40: 39 | CT40: 39 | CU40: 39 | CV40: 39 | CW40: 39
...

Sheet NODOS
A1: Nodo_Ini | B1: Nodo_Fin | C1: SED NodoFin | D1: Clientes | E1: Longitud (m) | F1: Long1 | G1: Long2 | H1: Long3 | I1: Long4 | J1: Long5 | K1: Long6 | L1: Long7 | M1: Long8 | N1: Long9 | O1: Long10 | P1: Long11 | Q1: Long12 | R1: Long13 | S1: Long14 | T1: Long15 | X1: ID_Tramo | Y1: Tramo_Anterior | Z1: Orden | AA1: Longitud (m)
A2: 0 | B2: 1 | E2: =SUM(F2:T2) -> 553.49 | F2: 28.45 | G2: 90.02 | H2: 90.22 | I2: 93.03 | J2: 48.01 | K2: 38.54 | L2: 89.08 | M2: 76.14 | X2: {=_xlfn._xlws.SORT('A4206 - Orden1'!$A$2:$D$288,3,1)} -> 9249850 | Y2: 0 | Z2: 1 | AA2: 28.45
A3: 1 | B3: 2 | C3: 1 | D3: 76 | E3: =SUM(F3:T3) -> 9.29 | F3: 9.29 | X3: 2167949 | Y3: 9249850 | Z3: 2 | AA3: 90.02
A4: 1 | B4: 3 | E4: =SUM(F4:T4) -> 546.24 | F4: 11.18 | G4: 83.97 | H4: 71.81 | I4: 68.9 | J4: 59.8 | K4: 1.01 | L4: 14.09 | M4: 31.04 | N4: 85.89 | O4: 2.98 | P4: 1.17 | Q4: 61.42 | R4: 52.98 | X4: 2167956 | Y4: 2167949 | Z4: 3 | AA4: 90.22
A5: 3 | B5: 4 | C5: 1 | D5: 151 | E5: =SUM(F5:T5) -> 26.91 | F5: 26.91 | X5: 2167963 | Y5: 2167956 | Z5: 4 | AA5: 93.03
A6: 3 | B6: 5 | E6: =SUM(F6:T6) -> 136.25 | F6: 3.12 | G6: 68.7 | H6: 59.57 | I6: 1.39 | J6: 3.47 | X6: 2167970 | Y6: 2167963 | Z6: 5 | AA6: 48.01
A7: 5 | B7: 6 | C7: 1 | D7: 86 | E7: =SUM(F7:T7) -> 48.66 | F7: 48.66 | X7: 2167977 | Y7: 2167970 | Z7: 6 | AA7: 38.54
A8: 5 | B8: 7 | E8: =SUM(F8:T8) -> 155.97 | F8: 22.62 | G8: 22.55 | H8: 1.9 | I8: 74.13 | J8: 34.77 | X8: 2167984 | Y8: 2167977 | Z8: 7 | AA8: 89.08
A9: 7 | B9: 8 | C9: 1 | D9: 108 | E9: =SUM(F9:T9) -> 150.88 | F9: 31.28 | G9: 60 | H9: 59.6 | X9: 7869054 | Y9: 2167984 | Z9: 8 | AA9: 76.14
A10: 7 | B10: 9 | E10: =SUM(F10:T10) -> 22.8 | F10: 22.8 | X10: 2167991 | Y10: 7869054 | Z10: 9 | AA10: 11.18
A11: 7 | B11: 10 | C11: 1 | D11: 26 | E11: =SUM(F11:T11) -> 169.42 | F11: 28.35 | G11: 62.9 | H11: 78.17 | X11: 7869061 | Y11: 7869054 | Z11: 9 | AA11: 9.29
A12: 10 | B12: 11 | C12: 1 | D12: 126 | E12: =SUM(F12:T12) -> 344.33 | F12: 73.03 | G12: 47.34 | H12: 36.69 | I12: 45.74 | J12: 69.89 | K12: 71.64 | X12: 2167998 | Y12: 2167991 | Z12: 10 | AA12: 83.97
A13: 11 | B13: 12 | E13: =SUM(F13:T13) -> 16.11 | F13: 16.11 | X13: 2168005 | Y13: 2167998 | Z13: 11 | AA13: 71.81
A14: 11 | B14: 13 | E14: =SUM(F14:T14) -> 254.12 | F14: 62.4 | G14: 64.4 | H14: 64.66 | I14: 62.66 | X14: 2168012 | Y14: 2168005 | Z14: 12 | AA14: 68.9
A15: 13 | B15: 14 | C15: 1 | D15: 158 | E15: =SUM(F15:T15) -> 26.31 | F15: 26.31 | X15: 2168019 | Y15: 2168012 | Z15: 13 | AA15: 59.8
A16: 13 | B16: 15 | E16: =SUM(F16:T16) -> 258.32 | F16: 54.92 | G16: 64.59 | H16: 70.68 | I16: 68.13 | X16: 9250025 | Y16: 2168019 | Z16: 14 | AA16: 1.01
A17: 15 | B17: 16 | C17: 1 | D17: 128 | E17: =SUM(F17:T17) -> 106.17 | F17: 23.93 | G17: 34.27 | H17: 47.97 | X17: 9250030 | Y17: 9250025 | Z17: 15 | AA17: 14.09
A18: 16 | B18: 17 | C18: 1 | D18: 141 | E18: =SUM(F18:T18) -> 135.58 | F18: 62.16 | G18: 58.32 | H18: 15.1 | X18: 9250035 | Y18: 9250030 | Z18: 16 | AA18: 31.04
A19: 17 | B19: 18 | C19: 1 | D19: 179 | E19: =SUM(F19:T19) -> 129.44 | F19: 54.28 | G19: 45 | H19: 30.16 | X19: 9250040 | Y19: 9250035 | Z19: 17 | AA19: 85.89
A20: 18 | B20: 19 | E20: =SUM(F20:T20) -> 165.55 | F20: 44.96 | G20: 49.98 | H20: 70.61 | X20: 9250045 | Y20: 9250040 | Z20: 18 | AA20: 2.98
A21: 15 | B21: 20 | E21: =SUM(F21:T21) -> 162 | F21: 24.98 | G21: 52 | H21: 67.78 | I21: 1.46 | J21: 15.78 | X21: 2168026 | Y21: 9250045 | Z21: 19 | AA21: 1.17
